Workbook

Sheet dataset 1992-2025
A1: TIME_PERIOD | B1: Yt | C1: t
A2: 1992-M01 | B2: 8.75 | C2: 1
A3: 1992-M02 | B3: 7.9 | C3: 2
A4: 1992-M03 | B4: 7.75 | C4: 3
A5: 1992-M04 | B5: 7.75 | C5: 4
A6: 1992-M05 | B6: 7.55 | C6: 5
A7: 1992-M06 | B7: 7.75 | C7: 6
A8: 1992-M07 | B8: 7.75 | C8: 7
A9: 1992-M08 | B9: 8.05 | C9: 8
A10: 1992-M09 | B10: 8.75 | C10: 9
A11: 1992-M10 | B11: 10.25 | C11: 10
A12: 1992-M11 | B12: 10.5 | C12: 11
A13: 1992-M12 | B13: 10 | C13: 12
... A407: 2025-M10 | B407: 63.958773 | C407: 406

Sheet dataset 2011-2025
A1: TIME_PERIOD | B1: Années | C1: Mois | D1: Yt | E1: t
A2: 2011-M01 | B2: =LEFT(TRIM(dataset_2025_11_17T13_30_33_170025752Z_DEFAULT_INTEGRATION_IMF_RES_PCPS_9_0_0[[#This Row],[TIME_PERIOD]]),4) -> 2011 | C2: =RIGHT(TRIM(dataset_2025_11_17T13_30_33_170025752Z_DEFAULT_INTEGRATION_IMF_RES_PCPS_9_0_0[[#This Row],[TIME_PERIOD]]),2) -> 01 | D2: 63.875 | E2: 1 | G2: Somme de Yt | H2: Mois
A3: 2011-M02 | B3: =LEFT(TRIM(dataset_2025_11_17T13_30_33_170025752Z_DEFAULT_INTEGRATION_IMF_RES_PCPS_9_0_0[[#This Row],[TIME_PERIOD]]),4) -> 2011 | C3: =RIGHT(TRIM(dataset_2025_11_17T13_30_33_170025752Z_DEFAULT_INTEGRATION_IMF_RES_PCPS_9_0_0[[#This Row],[TIME_PERIOD]]),2) -> 02 | D3: 65 | E3: 2 | G3: Années | H3: 1 | I3: 2 | J3: 3 | K3: 4 | L3: 5 | M3: 6 | N3: 7 | O3: 8 | P3: 9 | Q3: 10 | R3: 11 | S3: 12 | T3: Total général | U3: Moyenne générale | V3: Taux de croissance annuel | X3: Min | Y3: Q1 | Z3: Me | AA3: Q3 | AB3: Max | AC3: Ecart-type | AD3: Ecart-interquartile à la médiane | AE3: CV
A4: 2011-M03 | B4: =LEFT(TRIM(dataset_2025_11_17T13_30_33_170025752Z_DEFAULT_INTEGRATION_IMF_RES_PCPS_9_0_0[[#This Row],[TIME_PERIOD]]),4) -> 2011 | C4: =RIGHT(TRIM(dataset_2025_11_17T13_30_33_170025752Z_DEFAULT_INTEGRATION_IMF_RES_PCPS_9_0_0[[#This Row],[TIME_PERIOD]]),2) -> 03 | D4: 63.5 | E4: 3 | G4: 2011 | H4: 63.88 | I4: 65 | J4: 63.5 | K4: 57.82 | L4: 56.06 | M4: 55.4 | N4: 52.79 | O4: 50.68 | P4: 51.98 | Q4: 52.34 | R4: 53.19 | S4: 52.18 | T4: 674.83 | U4: 56.24 | X4: =MIN(H4:S4) -> 50.68 | Y4: =QUARTILE(H4:S4,1) -> 52.3 | Z4: =QUARTILE(I4:T4,2) -> 54.295 | AA4: =QUARTILE(J4:U4,3) -> 56.635 | AB4: =MAX(H4:S4) -> 65 | AC4: =_xlfn.STDEV.P(H4:S4) -> 4.9413957 | AD4: =(AA4-Y4)*100/Z4 -> 7.9841606 | AE4: =AC4*100/U4 -> 8.7862655
A5: 2011-M04 | B5: =LEFT(TRIM(dataset_2025_11_17T13_30_33_170025752Z_DEFAULT_INTEGRATION_IMF_RES_PCPS_9_0_0[[#This Row],[TIME_PERIOD]]),4) -> 2011 | C5: =RIGHT(TRIM(dataset_2025_11_17T13_30_33_170025752Z_DEFAULT_INTEGRATION_IMF_RES_PCPS_9_0_0[[#This Row],[TIME_PERIOD]]),2) -> 04 | D5: 57.821429 | E5: 4 | G5: 2012 | H5: 52.31 | I5: 52.06 | J5: 51.29 | K5: 51.3 | L5: 51.89 | M5: 50.83 | N5: 50.36 | O5: 49.25 | P5: 47.73 | Q5: 44.61 | R5: 41.5 | S5: 43.67 | T5: 586.79 | U5: 48.9 | V5: =(U5-U4)*100/U4 -> -13.051209 | X5: =MIN(H5:S5) -> 41.5 | Y5: =QUARTILE(H5:S5,1) -> 46.95 | Z5: =QUARTILE(I5:T5,2) -> 50.595 | AA5: =QUARTILE(J5:U5,3) -> 51.2925 | AB5: =MAX(H5:S5) -> 52.31 | AC5: =_xlfn.STDEV.P(H5:S5) -> 3.5342467 | AD5: =(AA5-Y5)*100/Z5 -> 8.5828639 | AE5: =AC5*100/U5 -> 7.2274984
A6: 2011-M05 | B6: =LEFT(TRIM(dataset_2025_11_17T13_30_33_170025752Z_DEFAULT_INTEGRATION_IMF_RES_PCPS_9_0_0[[#This Row],[TIME_PERIOD]]),4) -> 2011 | C6: =RIGHT(TRIM(dataset_2025_11_17T13_30_33_170025752Z_DEFAULT_INTEGRATION_IMF_RES_PCPS_9_0_0[[#This Row],[TIME_PERIOD]]),2) -> 05 | D6: 56.0625 | E6: 5 | G6: 2013 | H6: 42.75 | I6: 43.41 | J6: 42.28 | K6: 41.41 | L6: 40.61 | M6: 39.94 | N6: 38.02 | O6: 34.99 | P6: 34.45 | Q6: 34.85 | R6: 35.59 | S6: 34.59 | T6: 462.9 | U6: 38.57 | V6: =(U6-U5)*100/U5 -> -21.124744 | X6: =MIN(H6:S6) -> 34.45 | Y6: =QUARTILE(H6:S6,1) -> 34.955 | Z6: =QUARTILE(I6:T6,2) -> 38.98 | AA6: =QUARTILE(J6:U6,3) -> 40.81 | AB6: =MAX(H6:S6) -> 43.41 | AC6: =_xlfn.STDEV.P(H6:S6) -> 3.3840126 | AD6: =(AA6-Y6)*100/Z6 -> 15.020523 | AE6: =AC6*100/U6 -> 8.7736908
A7: 2011-M06 | B7: =LEFT(TRIM(dataset_2025_11_17T13_30_33_170025752Z_DEFAULT_INTEGRATION_IMF_RES_PCPS_9_0_0[[#This Row],[TIME_PERIOD]]),4) -> 2011 | C7: =RIGHT(TRIM(dataset_2025_11_17T13_30_33_170025752Z_DEFAULT_INTEGRATION_IMF_RES_PCPS_9_0_0[[#This Row],[TIME_PERIOD]]),2) -> 06 | D7: 55.4 | E7: 6 | G7: 2014 | H7: 35.21 | I7: 35.55 | J7: 34.7 | K7: 32.74 | L7: 28.54 | M7: 28.23 | N7: 28.4 | O7: 30.83 | P7: 34.37 | Q7: 35.75 | R7: 40.6 | S7: 36.95 | T7: 401.87 | U7: 33.49 | V7: =(U7-U6)*100/U6 -> -13.170858 | X7: =MIN(H7:S7) -> 28.23 | Y7: =QUARTILE(H7:S7,1) -> 30.2575 | Z7: =QUARTILE(I7:T7,2) -> 34.535 | AA7: =QUARTILE(J7:U7,3) -> 36.05 | AB7: =MAX(H7:S7) -> 40.6 | AC7: =_xlfn.STDEV.P(H7:S7) -> 3.6831609 | AD7: =(AA7-Y7)*100/Z7 -> 16.772839 | AE7: =AC7*100/U7 -> 10.997793
A8: 2011-M07 | B8: =LEFT(TRIM(dataset_2025_11_17T13_30_33_170025752Z_DEFAULT_INTEGRATION_IMF_RES_PCPS_9_0_0[[#This Row],[TIME_PERIOD]]),4) -> 2011 | C8: =RIGHT(TRIM(dataset_2025_11_17T13_30_33_170025752Z_DEFAULT_INTEGRATION_IMF_RES_PCPS_9_0_0[[#This Row],[TIME_PERIOD]]),2) -> 07 | D8: 52.788889 | E8: 7 | G8: 2015 | H8: 35.9 | I8: 38.19 | J8: 39.32 | K8: 38.84 | L8: 35.69 | M8: 36.05 | N8: 36.28 | O8: 36.1 | P8: 37.06 | Q8: 37.24 | R8: 35.96 | S8: 35.16 | T8: 441.78 | U8: 36.82 | V8: =(U8-U7)*100/U7 -> 9.9432666 | X8: =MIN(H8:S8) -> 35.16 | Y8: =QUARTILE(H8:S8,1) -> 35.945 | Z8: =QUARTILE(I8:T8,2) -> 36.67 | AA8: =QUARTILE(J8:U8,3) -> 37.64 | AB8: =MAX(H8:S8) -> 39.32 | AC8: =_xlfn.STDEV.P(H8:S8) -> 1.2735283 | AD8: =(AA8-Y8)*100/Z8 -> 4.6223071 | AE8: =AC8*100/U8 -> 3.4587949
A9: 2011-M08 | B9: =LEFT(TRIM(dataset_2025_11_17T13_30_33_170025752Z_DEFAULT_INTEGRATION_IMF_RES_PCPS_9_0_0[[#This Row],[TIME_PERIOD]]),4) -> 2011 | C9: =RIGHT(TRIM(dataset_2025_11_17T13_30_33_170025752Z_DEFAULT_INTEGRATION_IMF_RES_PCPS_9_0_0[[#This Row],[TIME_PERIOD]]),2) -> 08 | D9: 50.683333 | E9: 8 | G9: 2016 | H9: 34.69 | I9: 34.01 | J9: 30.11 | K9: 27.82 | L9: 27.95 | M9: 27.35 | N9: 25.85 | O9: 25.9 | P9: 24.88 | Q9: 21.49 | R9: 18.57 | S9: 19.22 | T9: 317.82 | U9: 26.49 | V9: =(U9-U8)*100/U8 -> -28.055405 | X9: =MIN(H9:S9) -> 18.57 | Y9: =QUARTILE(H9:S9,1) -> 24.0325 | Z9: =QUARTILE(I9:T9,2) -> 26.625 | AA9: =QUARTILE(J9:U9,3) -> 27.8525 | AB9: =MAX(H9:S9) -> 34.69 | AC9: =_xlfn.STDEV.P(H9:S9) -> 4.8773615 | AD9: =(AA9-Y9)*100/Z9 -> 14.347418 | AE9: =AC9*100/U9 -> 18.412086
A10: 2011-M09 | B10: =LEFT(TRIM(dataset_2025_11_17T13_30_33_170025752Z_DEFAULT_INTEGRATION_IMF_RES_PCPS_9_0_0[[#This Row],[TIME_PERIOD]]),4) -> 2011 | C10: =RIGHT(TRIM(dataset_2025_11_17T13_30_33_170025752Z_DEFAULT_INTEGRATION_IMF_RES_PCPS_9_0_0[[#This Row],[TIME_PERIOD]]),2) -> 09 | D10: 51.983333 | E10: 9 | G10: 2017 | H10: 22.17 | I10: 25.15 | J10: 24.64 | K10: 23.25 | L10: 21.64 | M10: 19.75 | N10: 20.36 | O10: 20.41 | P10: 20.43 | Q10: 20.23 | R10: 22.35 | S10: 24.69 | T10: 265.07 | U10: 22.09 | V10: =(U10-U9)*100/U9 -> -16.610042 | X10: =MIN(H10:S10) -> 19.75 | Y10: =QUARTILE(H10:S10,1) -> 20.3975 | Z10: =QUARTILE(I10:T10,2) -> 21.995 | AA10: =QUARTILE(J10:U10,3) -> 23.5975 | AB10: =MAX(H10:S10) -> 25.15 | AC10: =_xlfn.STDEV.P(H10:S10) -> 1.8653483 | AD10: =(AA10-Y10)*100/Z10 -> 14.548761 | AE10: =AC10*100/U10 -> 8.444311
A11: 2011-M10 | B11: =LEFT(TRIM(dataset_2025_11_17T13_30_33_170025752Z_DEFAULT_INTEGRATION_IMF_RES_PCPS_9_0_0[[#This Row],[TIME_PERIOD]]),4) -> 2011 | C11: =RIGHT(TRIM(dataset_2025_11_17T13_30_33_170025752Z_DEFAULT_INTEGRATION_IMF_RES_PCPS_9_0_0[[#This Row],[TIME_PERIOD]]),2) -> 10 | D11: 52.3375 | E11: 10 | G11: 2018 | H11: 23.37 | I11: 21.76 | J11: 21.73 | K11: 20.85 | L11: 21.98 | M11: 23.07 | N11: 23.42 | O11: 26.05 | P11: 27.11 | Q11: 27.51 | R11: 28.93 | S11: 28.76 | T11: 294.53 | U11: 24.54 | V11: =(U11-U10)*100/U10 -> 11.090991 | X11: =MIN(H11:S11) -> 20.85 | Y11: =QUARTILE(H11:S11,1) -> 21.925 | Z11: =QUARTILE(I11:T11,2) -> 24.735 | AA11: =QUARTILE(J11:U11,3) -> 27.8225 | AB11: =MAX(H11:S11) -> 28.93 | AC11: =_xlfn.STDEV.P(H11:S11) -> 2.8190498 | AD11: =(AA11-Y11)*100/Z11 -> 23.842733 | AE11: =AC11*100/U11 -> 11.48757
A12: 2011-M11 | B12: =LEFT(TRIM(dataset_2025_11_17T13_30_33_170025752Z_DEFAULT_INTEGRATION_IMF_RES_PCPS_9_0_0[[#This Row],[TIME_PERIOD]]),4) -> 2011 | C12: =RIGHT(TRIM(dataset_2025_11_17T13_30_33_170025752Z_DEFAULT_INTEGRATION_IMF_RES_PCPS_9_0_0[[#This Row],[TIME_PERIOD]]),2) -> 11 | D12: 53.194444 | E12: 11 | G12: 2019 | H12: 28.71 | I12: 28.65 | J12: 27.2 | K12: 25.7 | L12: 24.68 | M12: 24.48 | N12: 25.23 | O12: 25.28 | P12: 25.41 | Q12: 24.92 | R12: 24.99 | S12: 25.63 | T12: 310.88 | U12: 25.91 | V12: =(U12-U11)*100/U11 -> 5.5827221 | X12: =MIN(H12:S12) -> 24.48 | Y12: =QUARTILE(H12:S12,1) -> 24.9725 | Z12: =QUARTILE(I12:T12,2) -> 25.345 | AA12: =QUARTILE(J12:U12,3) -> 25.7525 | AB12: =MAX(H12:S12) -> 28.71 | AC12: =_xlfn.STDEV.P(H12:S12) -> 1.4032007 | AD12: =(AA12-Y12)*100/Z12 -> 3.0775301 | AE12: =AC12*100/U12 -> 5.4156724
A13: 2011-M12 | B13: =LEFT(TRIM(dataset_2025_11_17T13_30_33_170025752Z_DEFAULT_INTEGRATION_IMF_RES_PCPS_9_0_0[[#This Row],[TIME_PERIOD]]),4) -> 2011 | C13: =RIGHT(TRIM(dataset_2025_11_17T13_30_33_170025752Z_DEFAULT_INTEGRATION_IMF_RES_PCPS_9_0_0[[#This Row],[TIME_PERIOD]]),2) -> 12 | D13: 52.178571 | E13: 12 | G13: 2020 | H13: 24.64 | I13: 24.69 | J13: 24.66 | K13: 29.96 | L13: 33.51 | M13: 33.09 | N13: 32.36 | O13: 31.38 | P13: 29.98 | Q13: 29.64 | R13: 29.49 | S13: 29.77 | T13: 353.17 | U13: 29.43 | V13: =(U13-U12)*100/U12 -> 13.585488 | X13: =MIN(H13:S13) -> 24.64 | Y13: =QUARTILE(H13:S13,1) -> 28.29 | Z13: =QUARTILE(I13:T13,2) -> 29.97 | AA13: =QUARTILE(J13:U13,3) -> 32.5425 | AB13: =MAX(H13:S13) -> 33.51 | AC13: =_xlfn.STDEV.P(H13:S13) -> 3.0460451 | AD13: =(AA13-Y13)*100/Z13 -> 14.189189 | AE13: =AC13*100/U13 -> 10.350136
A14: 2012-M01 | B14: =LEFT(TRIM(dataset_2025_11_17T13_30_33_170025752Z_DEFAULT_INTEGRATION_IMF_RES_PCPS_9_0_0[[#This Row],[TIME_PERIOD]]),4) -> 2012 | C14: =RIGHT(TRIM(dataset_2025_11_17T13_30_33_170025752Z_DEFAULT_INTEGRATION_IMF_RES_PCPS_9_0_0[[#This Row],[TIME_PERIOD]]),2) -> 01 | D14: 52.3125 | E14: 13 | G14: 2021 | H14: 29.86 | I14: 28.66 | J14: 28.33 | K14: 29.75 | L14: 30.26 | M14: 32.14 | N14: 32.34 | O14: 32.15 | P14: 45.08 | Q14: 38.48 | R14: 31.1 | S14: 36.13 | T14: 394.28 | U14: 32.86 | V14: =(U14-U13)*100/U13 -> 11.654774 | X14: =MIN(H14:S14) -> 28.33 | Y14: =QUARTILE(H14:S14,1) -> 29.8325 | Z14: =QUARTILE(I14:T14,2) -> 32.145 | AA14: =QUARTILE(J14:U14,3) -> 36.7175 | AB14: =MAX(H14:S14) -> 45.08 | AC14: =_xlfn.STDEV.P(H14:S14) -> 4.6510668 | AD14: =(AA14-Y14)*100/Z14 -> 21.418572 | AE14: =AC14*100/U14 -> 14.15419
A15: 2012-M02 | B15: =LEFT(TRIM(dataset_2025_11_17T13_30_33_170025752Z_DEFAULT_INTEGRATION_IMF_RES_PCPS_9_0_0[[#This Row],[TIME_PERIOD]]),4) -> 2012 | C15: =RIGHT(TRIM(dataset_2025_11_17T13_30_33_170025752Z_DEFAULT_INTEGRATION_IMF_RES_PCPS_9_0_0[[#This Row],[TIME_PERIOD]]),2) -> 02 | D15: 52.055556 | E15: 14 | G15: 2022 | H15: 36.87 | I15: 35.83 | J15: 45.51 | K15: 48.7 | L15: 40.89 | M15: 40.33 | N15: 38.94 | O15: 39.8 | P15: 40.95 | Q15: 41.3 | R15: 40.95 | S15: 39.18 | T15: 489.28 | U15: 40.77 | V15: =(U15-U14)*100/U14 -> 24.07182 | X15: =MIN(H15:S15) -> 35.83 | Y15: =QUARTILE(H15:S15,1) -> 39.12 | Z15: =QUARTILE(I15:T15,2) -> 40.92 | AA15: =QUARTILE(J15:U15,3) -> 42.3525 | AB15: =MAX(H15:S15) -> 48.7 | AC15: =_xlfn.STDEV.P(H15:S15) -> 3.3208645 | AD15: =(AA15-Y15)*100/Z15 -> 7.8995601 | AE15: =AC15*100/U15 -> 8.145363
A16: 2012-M03 | B16: =LEFT(TRIM(dataset_2025_11_17T13_30_33_170025752Z_DEFAULT_INTEGRATION_IMF_RES_PCPS_9_0_0[[#This Row],[TIME_PERIOD]]),4) -> 2012 | C16: =RIGHT(TRIM(dataset_2025_11_17T13_30_33_170025752Z_DEFAULT_INTEGRATION_IMF_RES_PCPS_9_0_0[[#This Row],[TIME_PERIOD]]),2) -> 03 | D16: 51.288889 | E16: 15 | G16: 2023 | H16: 40.06 | I16: 41.31 | J16: 40.74 | K16: 41.76 | L16: 43.46 | M16: 45.7 | N16: 45.25 | O16: 46.38 | P16: 53.2 | Q16: 57.65 | R16: 62.29 | S16: 70.06 | T16: 587.86 | U16: 48.99 | V16: =(U16-U15)*100/U15 -> 20.161884 | X16: =MIN(H16:S16) -> 40.06 | Y16: =QUARTILE(H16:S16,1) -> 41.6475 | Z16: =QUARTILE(I16:T16,2) -> 46.04 | AA16: =QUARTILE(J16:U16,3) -> 58.81 | AB16: =MAX(H16:S16) -> 70.06 | AC16: =_xlfn.STDEV.P(H16:S16) -> 9.286289 | AD16: =(AA16-Y16)*100/Z16 -> 37.277368 | AE16: =AC16*100/U16 -> 18.955479
A17: 2012-M04 | B17: =LEFT(TRIM(dataset_2025_11_17T13_30_33_170025752Z_DEFAULT_INTEGRATION_IMF_RES_PCPS_9_0_0[[#This Row],[TIME_PERIOD]]),4) -> 2012 | C17: =RIGHT(TRIM(dataset_2025_11_17T13_30_33_170025752Z_DEFAULT_INTEGRATION_IMF_RES_PCPS_9_0_0[[#This Row],[TIME_PERIOD]]),2) -> 04 | D17: 51.3 | E17: 16 | G17: 2024 | H17: 80.36 | I17: 81.32 | J17: 71.81 | K17: 71.64 | L17: 73.95 | M17: 69.19 | N17: 68.25 | O17: 65.29 | P17: 64.63 | Q17: 66.51 | R17: 63.16 | S17: 60.22 | T17: 836.33 | U17: 69.69 | V17: =(U17-U16)*100/U16 -> 42.253521 | X17: =MIN(H17:S17) -> 60.22 | Y17: =QUARTILE(H17:S17,1) -> 65.125 | Z17: =QUARTILE(I17:T17,2) -> 68.72 | AA17: =QUARTILE(J17:U17,3) -> 71.6825 | AB17: =MAX(H17:S17) -> 81.32 | AC17: =_xlfn.STDEV.P(H17:S17) -> 6.2267668 | AD17: =(AA17-Y17)*100/Z17 -> 9.5423458 | AE17: =AC17*100/U17 -> 8.9349502
A18: 2012-M05 | B18: =LEFT(TRIM(dataset_2025_11_17T13_30_33_170025752Z_DEFAULT_INTEGRATION_IMF_RES_PCPS_9_0_0[[#This Row],[TIME_PERIOD]]),4) -> 2012 | C18: =RIGHT(TRIM(dataset_2025_11_17T13_30_33_170025752Z_DEFAULT_INTEGRATION_IMF_RES_PCPS_9_0_0[[#This Row],[TIME_PERIOD]]),2) -> 05 | D18: 51.888889 | E18: 17 | G18: 2025 | H18: 58.96 | I18: 54.32 | J18: 51.83 | K18: 52.69 | L18: 57.31 | M18: 59.58 | N18: 58.95 | O18: 58.97 | P18: 62.88 | Q18: 63.96 | T18: 579.43 | U18: 57.94 | V18: =(U18-U17)*100/U17 -> -16.860382 | X18: =MIN(H18:S18) -> 51.83 | Y18: =QUARTILE(H18:S18,1) -> 55.0675 | Z18: =QUARTILE(I18:T18,2) -> 58.96 | AA18: =QUARTILE(J18:U18,3) -> 62.055 | AB18: =MAX(H18:S18) -> 63.96 | AC18: =_xlfn.STDEV.P(H18:S18) -> 3.805925 | AD18: =(AA18-Y18)*100/Z18 -> 11.851255 | AE18: =AC18*100/U18 -> 6.5687349
A19: 2012-M06 | B19: =LEFT(TRIM(dataset_2025_11_17T13_30_33_170025752Z_DEFAULT_INTEGRATION_IMF_RES_PCPS_9_0_0[[#This Row],[TIME_PERIOD]]),4) -> 2012 | C19: =RIGHT(TRIM(dataset_2025_11_17T13_30_33_170025752Z_DEFAULT_INTEGRATION_IMF_RES_PCPS_9_0_0[[#This Row],[TIME_PERIOD]]),2) -> 06 | D19: 50.833333 | E19: 18 | G19: Total général | H19: 609.74936 | I19: 609.89068 | J19: 597.67017 | K19: 594.2425 | L19: 588.42472 | M19: 585.11695 | N19: 576.78848 | O19: 573.45124 | P19: 600.1323 | Q19: 596.46817 | R19: 528.66802 | S19: 536.20426 | T19: 6996.8069 | U19: 583.06724
A20: 2012-M07 | B20: =LEFT(TRIM(dataset_2025_11_17T13_30_33_170025752Z_DEFAULT_INTEGRATION_IMF_RES_PCPS_9_0_0[[#This Row],[TIME_PERIOD]]),4) -> 2012 | C20: =RIGHT(TRIM(dataset_2025_11_17T13_30_33_170025752Z_DEFAULT_INTEGRATION_IMF_RES_PCPS_9_0_0[[#This Row],[TIME_PERIOD]]),2) -> 07 | D20: 50.355556 | E20: 19 | G20: Coefficients saisonniers St | H20: =AVERAGE(H4:H18) -> 40.649333 | I20: =AVERAGE(I4:I18) -> 40.660667 | J20: =AVERAGE(J4:J18) -> 39.843333 | K20: =AVERAGE(K4:K18) -> 39.615333 | L20: =AVERAGE(L4:L18) -> 39.228 | M20: =AVERAGE(M4:M18) -> 39.008667 | N20: =AVERAGE(N4:N18) -> 38.453333 | O20: =AVERAGE(O4:O18) -> 38.230667 | ... S20: =AVERAGE(S4:S18) -> 38.300714
A21: 2012-M08 | B21: =LEFT(TRIM(dataset_2025_11_17T13_30_33_170025752Z_DEFAULT_INTEGRATION_IMF_RES_PCPS_9_0_0[[#This Row],[TIME_PERIOD]]),4) -> 2012 | C21: =RIGHT(TRIM(dataset_2025_11_17T13_30_33_170025752Z_DEFAULT_INTEGRATION_IMF_RES_PCPS_9_0_0[[#This Row],[TIME_PERIOD]]),2) -> 08 | D21: 49.25 | E21: 20
A22: 2012-M09 | B22: =LEFT(TRIM(dataset_2025_11_17T13_30_33_170025752Z_DEFAULT_INTEGRATION_IMF_RES_PCPS_9_0_0[[#This Row],[TIME_PERIOD]]),4) -> 2012 | C22: =RIGHT(TRIM(dataset_2025_11_17T13_30_33_170025752Z_DEFAULT_INTEGRATION_IMF_RES_PCPS_9_0_0[[#This Row],[TIME_PERIOD]]),2) -> 09 | D22: 47.725 | E22: 21
A23: 2012-M10 | B23: =LEFT(TRIM(dataset_2025_11_17T13_30_33_170025752Z_DEFAULT_INTEGRATION_IMF_RES_PCPS_9_0_0[[#This Row],[TIME_PERIOD]]),4) -> 2012 | C23: =RIGHT(TRIM(dataset_2025_11_17T13_30_33_170025752Z_DEFAULT_INTEGRATION_IMF_RES_PCPS_9_0_0[[#This Row],[TIME_PERIOD]]),2) -> 10 | D23: 44.611111 | E23: 22
A24: 2012-M11 | B24: =LEFT(TRIM(dataset_2025_11_17T13_30_33_170025752Z_DEFAULT_INTEGRATION_IMF_RES_PCPS_9_0_0[[#This Row],[TIME_PERIOD]]),4) -> 2012 | C24: =RIGHT(TRIM(dataset_2025_11_17T13_30_33_170025752Z_DEFAULT_INTEGRATION_IMF_RES_PCPS_9_0_0[[#This Row],[TIME_PERIOD]]),2) -> 11 | D24: 41.5 | E24: 23
A25: 2012-M12 | B25: =LEFT(TRIM(dataset_2025_11_17T13_30_33_170025752Z_DEFAULT_INTEGRATION_IMF_RES_PCPS_9_0_0[[#This Row],[TIME_PERIOD]]),4) -> 2012 | C25: =RIGHT(TRIM(dataset_2025_11_17T13_30_33_170025752Z_DEFAULT_INTEGRATION_IMF_RES_PCPS_9_0_0[[#This Row],[TIME_PERIOD]]),2) -> 12 | D25: 43.666667 | E25: 24 | G25: La valeur max a été observée en 2024 et la plus basse en 2017.
A26: 2013-M01 | B26: =LEFT(TRIM(dataset_2025_11_17T13_30_33_170025752Z_DEFAULT_INTEGRATION_IMF_RES_PCPS_9_0_0[[#This Row],[TIME_PERIOD]]),4) -> 2013 | C26: =RIGHT(TRIM(dataset_2025_11_17T13_30_33_170025752Z_DEFAULT_INTEGRATION_IMF_RES_PCPS_9_0_0[[#This Row],[TIME_PERIOD]]),2) -> 01 | D26: 42.75 | E26: 25
A27: 2013-M02 | B27: =LEFT(TRIM(dataset_2025_11_17T13_30_33_170025752Z_DEFAULT_INTEGRATION_IMF_RES_PCPS_9_0_0[[#This Row],[TIME_PERIOD]]),4) -> 2013 | C27: =RIGHT(TRIM(dataset_2025_11_17T13_30_33_170025752Z_DEFAULT_INTEGRATION_IMF_RES_PCPS_9_0_0[[#This Row],[TIME_PERIOD]]),2) -> 02 | D27: 43.40625 | E27: 26 | G27: La moyenne mensuel s'élève à | J27: =AVERAGE(U4:U18) -> 39.515333
A28: 2013-M03 | B28: =LEFT(TRIM(dataset_2025_11_17T13_30_33_170025752Z_DEFAULT_INTEGRATION_IMF_RES_PCPS_9_0_0[[#This Row],[TIME_PERIOD]]),4) -> 2013 | C28: =RIGHT(TRIM(dataset_2025_11_17T13_30_33_170025752Z_DEFAULT_INTEGRATION_IMF_RES_PCPS_9_0_0[[#This Row],[TIME_PERIOD]]),2) -> 03 | D28: 42.28125 | E28: 27 | G28: L'écart-type ressort autour de | J28: =_xlfn.STDEV.P(U4:U18) -> 13.619218
A29: 2013-M04 | B29: =LEFT(TRIM(dataset_2025_11_17T13_30_33_170025752Z_DEFAULT_INTEGRATION_IMF_RES_PCPS_9_0_0[[#This Row],[TIME_PERIOD]]),4) -> 2013 | C29: =RIGHT(TRIM(dataset_2025_11_17T13_30_33_170025752Z_DEFAULT_INTEGRATION_IMF_RES_PCPS_9_0_0[[#This Row],[TIME_PERIOD]]),2) -> 04 | D29: 41.4125 | E29: 28 | G29: Le coefficient de variation vaut | J29: =J28/J27 -> 0.34465654
A30: 2013-M05 | B30: =LEFT(TRIM(dataset_2025_11_17T13_30_33_170025752Z_DEFAULT_INTEGRATION_IMF_RES_PCPS_9_0_0[[#This Row],[TIME_PERIOD]]),4) -> 2013 | C30: =RIGHT(TRIM(dataset_2025_11_17T13_30_33_170025752Z_DEFAULT_INTEGRATION_IMF_RES_PCPS_9_0_0[[#This Row],[TIME_PERIOD]]),2) -> 05 | D30: 40.605 | E30: 29 | G30: La série semble relativement peu dispersée autour de sa moyenne (0,34<0,5)
A31: 2013-M06 | B31: =LEFT(TRIM(dataset_2025_11_17T13_30_33_170025752Z_DEFAULT_INTEGRATION_IMF_RES_PCPS_9_0_0[[#This Row],[TIME_PERIOD]]),4) -> 2013 | C31: =RIGHT(TRIM(dataset_2025_11_17T13_30_33_170025752Z_DEFAULT_INTEGRATION_IMF_RES_PCPS_9_0_0[[#This Row],[TIME_PERIOD]]),2) -> 06 | D31: 39.9375 | E31: 30
A32: 2013-M07 | B32: =LEFT(TRIM(dataset_2025_11_17T13_30_33_170025752Z_DEFAULT_INTEGRATION_IMF_RES_PCPS_9_0_0[[#This Row],[TIME_PERIOD]]),4) -> 2013 | C32: =RIGHT(TRIM(dataset_2025_11_17T13_30_33_170025752Z_DEFAULT_INTEGRATION_IMF_RES_PCPS_9_0_0[[#This Row],[TIME_PERIOD]]),2) -> 07 | D32: 38.022222 | E32: 31 | G32: Taux de croissance mensuel moyen sur l'ensemble de la période | L32: =(U18-U4)/U4 -> 0.030227596
A33: 2013-M08 | B33: =LEFT(TRIM(dataset_2025_11_17T13_30_33_170025752Z_DEFAULT_INTEGRATION_IMF_RES_PCPS_9_0_0[[#This Row],[TIME_PERIOD]]),4) -> 2013 | C33: =RIGHT(TRIM(dataset_2025_11_17T13_30_33_170025752Z_DEFAULT_INTEGRATION_IMF_RES_PCPS_9_0_0[[#This Row],[TIME_PERIOD]]),2) -> 08 | D33: 34.994163 | E33: 32 | G33: L'uranium a connu une croissance entre 2011 et 2025(+3,04%). En d'autres termes, il a été multiplié par 1,03.
A34: 2013-M09 | B34: =LEFT(TRIM(dataset_2025_11_17T13_30_33_170025752Z_DEFAULT_INTEGRATION_IMF_RES_PCPS_9_0_0[[#This Row],[TIME_PERIOD]]),4) -> 2013 | C34: =RIGHT(TRIM(dataset_2025_11_17T13_30_33_170025752Z_DEFAULT_INTEGRATION_IMF_RES_PCPS_9_0_0[[#This Row],[TIME_PERIOD]]),2) -> 09 | D34: 34.453287 | E34: 33
A35: 2013-M10 | B35: =LEFT(TRIM(dataset_2025_11_17T13_30_33_170025752Z_DEFAULT_INTEGRATION_IMF_RES_PCPS_9_0_0[[#This Row],[TIME_PERIOD]]),4) -> 2013 | C35: =RIGHT(TRIM(dataset_2025_11_17T13_30_33_170025752Z_DEFAULT_INTEGRATION_IMF_RES_PCPS_9_0_0[[#This Row],[TIME_PERIOD]]),2) -> 10 | D35: 34.848496 | E35: 34
A36: 2013-M11 | B36: =LEFT(TRIM(dataset_2025_11_17T13_30_33_170025752Z_DEFAULT_INTEGRATION_IMF_RES_PCPS_9_0_0[[#This Row],[TIME_PERIOD]]),4) -> 2013 | C36: =RIGHT(TRIM(dataset_2025_11_17T13_30_33_170025752Z_DEFAULT_INTEGRATION_IMF_RES_PCPS_9_0_0[[#This Row],[TIME_PERIOD]]),2) -> 11 | D36: 35.592003 | E36: 35
A37: 2013-M12 | B37: =LEFT(TRIM(dataset_2025_11_17T13_30_33_170025752Z_DEFAULT_INTEGRATION_IMF_RES_PCPS_9_0_0[[#This Row],[TIME_PERIOD]]),4) -> 2013 | C37: =RIGHT(TRIM(dataset_2025_11_17T13_30_33_170025752Z_DEFAULT_INTEGRATION_IMF_RES_PCPS_9_0_0[[#This Row],[TIME_PERIOD]]),2) -> 12 | D37: 34.593297 | E37: 36
A38: 2014-M01 | B38: =LEFT(TRIM(dataset_2025_11_17T13_30_33_170025752Z_DEFAULT_INTEGRATION_IMF_RES_PCPS_9_0_0[[#This Row],[TIME_PERIOD]]),4) -> 2014 | C38: =RIGHT(TRIM(dataset_2025_11_17T13_30_33_170025752Z_DEFAULT_INTEGRATION_IMF_RES_PCPS_9_0_0[[#This Row],[TIME_PERIOD]]),2) -> 01 | D38: 35.214989 | E38: 37
A39: 2014-M02 | B39: =LEFT(TRIM(dataset_2025_11_17T13_30_33_170025752Z_DEFAULT_INTEGRATION_IMF_RES_PCPS_9_0_0[[#This Row],[TIME_PERIOD]]),4) -> 2014 | C39: =RIGHT(TRIM(dataset_2025_11_17T13_30_33_170025752Z_DEFAULT_INTEGRATION_IMF_RES_PCPS_9_0_0[[#This Row],[TIME_PERIOD]]),2) -> 02 | D39: 35.546739 | E39: 38
A40: 2014-M03 | B40: =LEFT(TRIM(dataset_2025_11_17T13_30_33_170025752Z_DEFAULT_INTEGRATION_IMF_RES_PCPS_9_0_0[[#This Row],[TIME_PERIOD]]),4) -> 2014 | C40: =RIGHT(TRIM(dataset_2025_11_17T13_30_33_170025752Z_DEFAULT_INTEGRATION_IMF_RES_PCPS_9_0_0[[#This Row],[TIME_PERIOD]]),2) -> 03 | D40: 34.702855 | E40: 39
...

Sheet Boite à moustache

Sheet Additf linéaire
D1: Série ajustée par seule la tendance linéaire (y^) | E1: Contributions à SR | F1: Contributions à ST | G1: Contributions à SM
A2: TIME_PERIOD | B2: Yt | C2: t | D2: ft=at+b =y^= 0,05*t+34,06 | E2: et^2=( y-y^) au carré | F2: (yt-ybar)^2 | G2: (yt^-ybar)^2
A3: 2011-M01 | B3: 63.875 | C3: 1 | D3: =$P$3*C3+$P$5 -> 34.12074 | E3: =(D3-B3)^2 -> 885.31597 | F3: =(B3-AVERAGE($B$3:$B$180))^2 -> 603.54222 | G3: =(D3-AVERAGE($B$3:$B$180))^2 -> 26.906664 | O3: a (pente) | P3: =SLOPE(B3:B180,C3:C180) -> 0.058612016
A4: 2011-M02 | B4: 65 | C4: 2 | D4: =$P$3*C4+$P$5 -> 34.179352 | E4: =(D4-B4)^2 -> 949.91233 | F4: =(B4-AVERAGE($B$3:$B$180))^2 -> 660.08381 | G4: =(D4-AVERAGE($B$3:$B$180))^2 -> 26.302039
A5: 2011-M03 | B5: 63.5 | C5: 3 | D5: =$P$3*C5+$P$5 -> 34.237964 | E5: =(D5-B5)^2 -> 856.26673 | F5: =(B5-AVERAGE($B$3:$B$180))^2 -> 585.25753 | G5: =(D5-AVERAGE($B$3:$B$180))^2 -> 25.704285 | O5: b (ordonnée à l'origine) | P5: =INTERCEPT(B3:B180,C3:C180) -> 34.062128
A6: 2011-M04 | B6: 57.821429 | C6: 4 | D6: =$P$3*C6+$P$5 -> 34.296576 | E6: =(D6-B6)^2 -> 553.41867 | F6: =(B6-AVERAGE($B$3:$B$180))^2 -> 342.7506 | G6: =(D6-AVERAGE($B$3:$B$180))^2 -> 25.113402
A7: 2011-M05 | B7: 56.0625 | C7: 5 | D7: =$P$3*C7+$P$5 -> 34.355188 | E7: =(D7-B7)^2 -> 471.20738 | F7: =(B7-AVERAGE($B$3:$B$180))^2 -> 280.7165 | G7: =(D7-AVERAGE($B$3:$B$180))^2 -> 24.529389 | O7: COV(t,Y) = | P7: =COVAR(B3:B180,C3:C180) -> 154.75038
A8: 2011-M06 | B8: 55.4 | C8: 6 | D8: =$P$3*C8+$P$5 -> 34.4138 | E8: =(D8-B8)^2 -> 440.42058 | F8: =(B8-AVERAGE($B$3:$B$180))^2 -> 258.95556 | G8: =(D8-AVERAGE($B$3:$B$180))^2 -> 23.952247
A9: 2011-M07 | B9: 52.788889 | C9: 7 | D9: =$P$3*C9+$P$5 -> 34.472412 | E9: =(D9-B9)^2 -> 335.49331 | F9: =(B9-AVERAGE($B$3:$B$180))^2 -> 181.73696 | G9: =(D9-AVERAGE($B$3:$B$180))^2 -> 23.381976 | O9: tbar = moy t | P9: =AVERAGE(C3:C180) -> 89.5
A10: 2011-M08 | B10: 50.683333 | C10: 8 | D10: =$P$3*C10+$P$5 -> 34.531024 | E10: =(D10-B10)^2 -> 260.89709 | F10: =(B10-AVERAGE($B$3:$B$180))^2 -> 129.4004 | G10: =(D10-AVERAGE($B$3:$B$180))^2 -> 22.818576
A11: 2011-M09 | B11: 51.983333 | C11: 9 | D11: =$P$3*C11+$P$5 -> 34.589636 | E11: =(D11-B11)^2 -> 302.54069 | F11: =(B11-AVERAGE($B$3:$B$180))^2 -> 160.66652 | G11: =(D11-AVERAGE($B$3:$B$180))^2 -> 22.262046 | O11: ybar = moy Y | P11: =AVERAGE(B3:B180) -> 39.307904
A12: 2011-M10 | B12: 52.3375 | C12: 10 | D12: =$P$3*C12+$P$5 -> 34.648248 | E12: =(D12-B12)^2 -> 312.90962 | F12: =(B12-AVERAGE($B$3:$B$180))^2 -> 169.77038 | G12: =(D12-AVERAGE($B$3:$B$180))^2 -> 21.712387
A13: 2011-M11 | B13: 53.194444 | C13: 11 | D13: =$P$3*C13+$P$5 -> 34.70686 | E13: =(D13-B13)^2 -> 341.79076 | F13: =(B13-AVERAGE($B$3:$B$180))^2 -> 192.83601 | G13: =(D13-AVERAGE($B$3:$B$180))^2 -> 21.169599 | O13: Equation de la tendance sous ajustement linéaire : | P13: y=0,059t + 34,06
A14: 2011-M12 | B14: 52.178571 | C14: 12 | D14: =$P$3*C14+$P$5 -> 34.765472 | E14: =(D14-B14)^2 -> 303.21602 | F14: =(B14-AVERAGE($B$3:$B$180))^2 -> 165.65409 | G14: =(D14-AVERAGE($B$3:$B$180))^2 -> 20.633682
A15: 2012-M01 | B15: 52.3125 | C15: 13 | D15: =$P$3*C15+$P$5 -> 34.824084 | E15: =(D15-B15)^2 -> 305.84468 | F15: =(B15-AVERAGE($B$3:$B$180))^2 -> 169.11953 | G15: =(D15-AVERAGE($B$3:$B$180))^2 -> 20.104635 | O15: Var(Y) = | P15: =VARP(B3:B180) -> 202.58894
A16: 2012-M02 | B16: 52.055556 | C16: 14 | D16: =$P$3*C16+$P$5 -> 34.882696 | E16: =(D16-B16)^2 -> 294.90709 | F16: =(B16-AVERAGE($B$3:$B$180))^2 -> 162.50263 | G16: =(D16-AVERAGE($B$3:$B$180))^2 -> 19.582459
A17: 2012-M03 | B17: 51.288889 | C17: 15 | D17: =$P$3*C17+$P$5 -> 34.941308 | E17: =(D17-B17)^2 -> 267.24339 | F17: =(B17-AVERAGE($B$3:$B$180))^2 -> 143.54401 | G17: =(D17-AVERAGE($B$3:$B$180))^2 -> 19.067154 | O17: Var(t) = | P17: =VARP(C3:C180) -> 2640.25
A18: 2012-M04 | B18: 51.3 | C18: 16 | D18: =$P$3*C18+$P$5 -> 34.99992 | E18: =(D18-B18)^2 -> 265.69259 | F18: =(B18-AVERAGE($B$3:$B$180))^2 -> 143.81037 | G18: =(D18-AVERAGE($B$3:$B$180))^2 -> 18.558719
A19: 2012-M05 | B19: 51.888889 | C19: 17 | D19: =$P$3*C19+$P$5 -> 35.058533 | E19: =(D19-B19)^2 -> 283.2609 | F19: =(B19-AVERAGE($B$3:$B$180))^2 -> 158.28119 | G19: =(D19-AVERAGE($B$3:$B$180))^2 -> 18.057155 | O19: R² | P19: =CORREL(B3:B180,C3:C180) -> 0.21159301
A20: 2012-M06 | B20: 50.833333 | C20: 18 | D20: =$P$3*C20+$P$5 -> 35.117145 | E20: =(D20-B20)^2 -> 246.99859 | F20: =(B20-AVERAGE($B$3:$B$180))^2 -> 132.83553 | G20: =(D20-AVERAGE($B$3:$B$180))^2 -> 17.562462
A21: 2012-M07 | B21: 50.355556 | C21: 19 | D21: =$P$3*C21+$P$5 -> 35.175757 | E21: =(D21-B21)^2 -> 230.4263 | F21: =(B21-AVERAGE($B$3:$B$180))^2 -> 122.05061 | G21: =(D21-AVERAGE($B$3:$B$180))^2 -> 17.07464
A22: 2012-M08 | B22: 49.25 | C22: 20 | D22: =$P$3*C22+$P$5 -> 35.234369 | E22: =(D22-B22)^2 -> 196.43792 | F22: =(B22-AVERAGE($B$3:$B$180))^2 -> 98.84528 | G22: =(D22-AVERAGE($B$3:$B$180))^2 -> 16.593688
A23: 2012-M09 | B23: 47.725 | C23: 21 | D23: =$P$3*C23+$P$5 -> 35.292981 | E23: =(D23-B23)^2 -> 154.55511 | F23: =(B23-AVERAGE($B$3:$B$180))^2 -> 70.847511 | G23: =(D23-AVERAGE($B$3:$B$180))^2 -> 16.119607
A24: 2012-M10 | B24: 44.611111 | C24: 22 | D24: =$P$3*C24+$P$5 -> 35.351593 | E24: =(D24-B24)^2 -> 85.738683 | F24: =(B24-AVERAGE($B$3:$B$180))^2 -> 28.124009 | G24: =(D24-AVERAGE($B$3:$B$180))^2 -> 15.652397
A25: 2012-M11 | B25: 41.5 | C25: 23 | D25: =$P$3*C25+$P$5 -> 35.410205 | E25: =(D25-B25)^2 -> 37.085608 | F25: =(B25-AVERAGE($B$3:$B$180))^2 -> 4.8052864 | G25: =(D25-AVERAGE($B$3:$B$180))^2 -> 15.192058
A26: 2012-M12 | B26: 43.666667 | C26: 24 | D26: =$P$3*C26+$P$5 -> 35.468817 | E26: =(D26-B26)^2 -> 67.204745 | F26: =(B26-AVERAGE($B$3:$B$180))^2 -> 18.998815 | G26: =(D26-AVERAGE($B$3:$B$180))^2 -> 14.738589
A27: 2013-M01 | B27: 42.75 | C27: 25 | D27: =$P$3*C27+$P$5 -> 35.527429 | E27: =(D27-B27)^2 -> 52.165537 | F27: =(B27-AVERAGE($B$3:$B$180))^2 -> 11.848027 | G27: =(D27-AVERAGE($B$3:$B$180))^2 -> 14.291991
A28: 2013-M02 | B28: 43.40625 | C28: 26 | D28: =$P$3*C28+$P$5 -> 35.586041 | E28: =(D28-B28)^2 -> 61.155674 | F28: =(B28-AVERAGE($B$3:$B$180))^2 -> 16.796443 | G28: =(D28-AVERAGE($B$3:$B$180))^2 -> 13.852264
A29: 2013-M03 | B29: 42.28125 | C29: 27 | D29: =$P$3*C29+$P$5 -> 35.644653 | E29: =(D29-B29)^2 -> 44.044424 | F29: =(B29-AVERAGE($B$3:$B$180))^2 -> 8.8407884 | G29: =(D29-AVERAGE($B$3:$B$180))^2 -> 13.419408
A30: 2013-M04 | B30: 41.4125 | C30: 28 | D30: =$P$3*C30+$P$5 -> 35.703265 | E30: =(D30-B30)^2 -> 32.595368 | F30: =(B30-AVERAGE($B$3:$B$180))^2 -> 4.4293257 | G30: =(D30-AVERAGE($B$3:$B$180))^2 -> 12.993422
A31: 2013-M05 | B31: 40.605 | C31: 29 | D31: =$P$3*C31+$P$5 -> 35.761877 | E31: =(D31-B31)^2 -> 23.455843 | F31: =(B31-AVERAGE($B$3:$B$180))^2 -> 1.6824589 | G31: =(D31-AVERAGE($B$3:$B$180))^2 -> 12.574307
... A180: 2025-M10 | B180: 63.958773 | C180: 178 | D180: =$P$3*C180+$P$5 -> 44.495067 | E180: =(D180-B180)^2 -> 378.83587 | F180: =(B180-AVERAGE($B$3:$B$180))^2 -> 607.66538 | G180: =(D180-AVERAGE($B$3:$B$180))^2 -> 26.906664
E183: SR | F183: ST = | G183: SM
E184: =SUM(E3:E180) -> 34446.331 | F184: =SUM(F3:F180) -> 36060.832 | G184: =SUM(G3:G180) -> 1614.5012
F185: R2 | G185: =G184/F184 -> 0.044771602

Sheet Additf quadratique
E1: Série ajustée par seule la tendance linéaire (y^) | F1: Contributions à ST | G1: Contributions à SM | H1: Contributions à SR
A2: TIME_PERIOD | B2: Yt | C2: t | D2: t² | E2: ft quadratique | F2: (Yt-ybar)^2 | G2: (yt^-ybar)^2 | H2: et^2=( y-y^) au carré
A3: 2011-M01 | B3: 63.875 | C3: 1 | D3: =C3^2 -> 1 | E3: =$Q$3*C3^2+$Q$5 -> 32.532585 | F3: =(B3-$Q$11)^2 -> 603.54222 | G3: =(E3-$Q$11)^2 -> 45.904941 | H3: =(B3-E3)^2 -> 982.34697 | P3: a (pente) | Q3: =SLOPE(B3:B180,D3:D180) -> 0.00063621001
A4: 2011-M02 | B4: 65 | C4: 2 | D4: =C4^2 -> 4 | E4: =$Q$3*C4^2+$Q$5 -> 32.534494 | F4: =(B4-$Q$11)^2 -> 660.08381 | G4: =(E4-$Q$11)^2 -> 45.879082 | H4: =(B4-E4)^2 -> 1054.0091
A5: 2011-M03 | B5: 63.5 | C5: 3 | D5: =C5^2 -> 9 | E5: =$Q$3*C5^2+$Q$5 -> 32.537675 | F5: =(B5-$Q$11)^2 -> 585.25753 | G5: =(E5-$Q$11)^2 -> 45.835999 | H5: =(B5-E5)^2 -> 958.66558 | P5: b (ordonnée à l'origine) | Q5: =INTERCEPT(B3:B180,D3:D180) -> 32.531949
A6: 2011-M04 | B6: 57.821429 | C6: 4 | D6: =C6^2 -> 16 | E6: =$Q$3*C6^2+$Q$5 -> 32.542128 | F6: =(B6-$Q$11)^2 -> 342.7506 | G6: =(E6-$Q$11)^2 -> 45.775716 | H6: =(B6-E6)^2 -> 639.04302
A7: 2011-M05 | B7: 56.0625 | C7: 5 | D7: =C7^2 -> 25 | E7: =$Q$3*C7^2+$Q$5 -> 32.547854 | F7: =(B7-$Q$11)^2 -> 280.7165 | G7: =(E7-$Q$11)^2 -> 45.698269 | H7: =(B7-E7)^2 -> 552.93857 | P7: COV(t²,Y) = | Q7: =COVAR(B3:B180,D3:D180) -> 57368.621
A8: 2011-M06 | B8: 55.4 | C8: 6 | D8: =C8^2 -> 36 | E8: =$Q$3*C8^2+$Q$5 -> 32.554852 | F8: =(B8-$Q$11)^2 -> 258.95556 | G8: =(E8-$Q$11)^2 -> 45.6037 | H8: =(B8-E8)^2 -> 521.90076
A9: 2011-M07 | B9: 52.788889 | C9: 7 | D9: =C9^2 -> 49 | E9: =$Q$3*C9^2+$Q$5 -> 32.563123 | F9: =(B9-$Q$11)^2 -> 181.73696 | G9: =(E9-$Q$11)^2 -> 45.492063 | H9: =(B9-E9)^2 -> 409.0816 | P9: tbar² = moy t | Q9: =AVERAGE(D3:D180) -> 10650.5
A10: 2011-M08 | B10: 50.683333 | C10: 8 | D10: =C10^2 -> 64 | E10: =$Q$3*C10^2+$Q$5 -> 32.572666 | F10: =(B10-$Q$11)^2 -> 129.4004 | G10: =(E10-$Q$11)^2 -> 45.363421 | H10: =(B10-E10)^2 -> 327.99626
A11: 2011-M09 | B11: 51.983333 | C11: 9 | D11: =C11^2 -> 81 | E11: =$Q$3*C11^2+$Q$5 -> 32.583482 | F11: =(B11-$Q$11)^2 -> 160.66652 | G11: =(E11-$Q$11)^2 -> 45.217848 | H11: =(B11-E11)^2 -> 376.35423 | P11: ybar = moy Y | Q11: =AVERAGE(B3:B180) -> 39.307904
A12: 2011-M10 | B12: 52.3375 | C12: 10 | D12: =C12^2 -> 100 | E12: =$Q$3*C12^2+$Q$5 -> 32.59557 | F12: =(B12-$Q$11)^2 -> 169.77038 | G12: =(E12-$Q$11)^2 -> 45.055424 | H12: =(B12-E12)^2 -> 389.7438
A13: 2011-M11 | B13: 53.194444 | C13: 11 | D13: =C13^2 -> 121 | E13: =$Q$3*C13^2+$Q$5 -> 32.60893 | F13: =(B13-$Q$11)^2 -> 192.83601 | G13: =(E13-$Q$11)^2 -> 44.876244 | H13: =(B13-E13)^2 -> 423.76339 | P13: Equation de la tendance sous ajustement linéaire : | Q13: y=0,00064t + 32,532
A14: 2011-M12 | B14: 52.178571 | C14: 12 | D14: =C14^2 -> 144 | E14: =$Q$3*C14^2+$Q$5 -> 32.623563 | F14: =(B14-$Q$11)^2 -> 165.65409 | G14: =(E14-$Q$11)^2 -> 44.680408 | H14: =(B14-E14)^2 -> 382.39835
A15: 2012-M01 | B15: 52.3125 | C15: 13 | D15: =C15^2 -> 169 | E15: =$Q$3*C15^2+$Q$5 -> 32.639468 | F15: =(B15-$Q$11)^2 -> 169.11953 | G15: =(E15-$Q$11)^2 -> 44.468029 | H15: =(B15-E15)^2 -> 387.02817 | P15: Var(Y) = | Q15: =VARP(B3:B180) -> 202.58894
A16: 2012-M02 | B16: 52.055556 | C16: 14 | D16: =C16^2 -> 196 | E16: =$Q$3*C16^2+$Q$5 -> 32.656646 | F16: =(B16-$Q$11)^2 -> 162.50263 | G16: =(E16-$Q$11)^2 -> 44.239227 | H16: =(B16-E16)^2 -> 376.31769
A17: 2012-M03 | B17: 51.288889 | C17: 15 | D17: =C17^2 -> 225 | E17: =$Q$3*C17^2+$Q$5 -> 32.675096 | F17: =(B17-$Q$11)^2 -> 143.54401 | G17: =(E17-$Q$11)^2 -> 43.994135 | H17: =(B17-E17)^2 -> 346.47328 | P17: Var(t²) = | Q17: =VARP(D3:D180) -> 90172458
A18: 2012-M04 | B18: 51.3 | C18: 16 | D18: =C18^2 -> 256 | E18: =$Q$3*C18^2+$Q$5 -> 32.694819 | F18: =(B18-$Q$11)^2 -> 143.81037 | G18: =(E18-$Q$11)^2 -> 43.732893 | H18: =(B18-E18)^2 -> 346.15277
A19: 2012-M05 | B19: 51.888889 | C19: 17 | D19: =C19^2 -> 289 | E19: =$Q$3*C19^2+$Q$5 -> 32.715814 | F19: =(B19-$Q$11)^2 -> 158.28119 | G19: =(E19-$Q$11)^2 -> 43.455651 | H19: =(B19-E19)^2 -> 367.60682 | P19: R² | Q19: =CORREL(B3:B180,D3:D180) -> 0.42445298
A20: 2012-M06 | B20: 50.833333 | C20: 18 | D20: =C20^2 -> 324 | E20: =$Q$3*C20^2+$Q$5 -> 32.738081 | F20: =(B20-$Q$11)^2 -> 132.83553 | G20: =(E20-$Q$11)^2 -> 43.16257 | H20: =(B20-E20)^2 -> 327.43816
A21: 2012-M07 | B21: 50.355556 | C21: 19 | D21: =C21^2 -> 361 | E21: =$Q$3*C21^2+$Q$5 -> 32.761621 | F21: =(B21-$Q$11)^2 -> 122.05061 | G21: =(E21-$Q$11)^2 -> 42.85382 | H21: =(B21-E21)^2 -> 309.54654
A22: 2012-M08 | B22: 49.25 | C22: 20 | D22: =C22^2 -> 400 | E22: =$Q$3*C22^2+$Q$5 -> 32.786433 | F22: =(B22-$Q$11)^2 -> 98.84528 | G22: =(E22-$Q$11)^2 -> 42.52958 | H22: =(B22-E22)^2 -> 271.04904
A23: 2012-M09 | B23: 47.725 | C23: 21 | D23: =C23^2 -> 441 | E23: =$Q$3*C23^2+$Q$5 -> 32.812518 | F23: =(B23-$Q$11)^2 -> 70.847511 | G23: =(E23-$Q$11)^2 -> 42.190041 | H23: =(B23-E23)^2 -> 222.38213
A24: 2012-M10 | B24: 44.611111 | C24: 22 | D24: =C24^2 -> 484 | E24: =$Q$3*C24^2+$Q$5 -> 32.839875 | F24: =(B24-$Q$11)^2 -> 28.124009 | G24: =(E24-$Q$11)^2 -> 41.8354 | H24: =(B24-E24)^2 -> 138.56201
A25: 2012-M11 | B25: 41.5 | C25: 23 | D25: =C25^2 -> 529 | E25: =$Q$3*C25^2+$Q$5 -> 32.868504 | F25: =(B25-$Q$11)^2 -> 4.8052864 | G25: =(E25-$Q$11)^2 -> 41.465868 | H25: =(B25-E25)^2 -> 74.502723
A26: 2012-M12 | B26: 43.666667 | C26: 24 | D26: =C26^2 -> 576 | E26: =$Q$3*C26^2+$Q$5 -> 32.898406 | F26: =(B26-$Q$11)^2 -> 18.998815 | G26: =(E26-$Q$11)^2 -> 41.081662 | H26: =(B26-E26)^2 -> 115.95544
A27: 2013-M01 | B27: 42.75 | C27: 25 | D27: =C27^2 -> 625 | E27: =$Q$3*C27^2+$Q$5 -> 32.92958 | F27: =(B27-$Q$11)^2 -> 11.848027 | G27: =(E27-$Q$11)^2 -> 40.68301 | H27: =(B27-E27)^2 -> 96.440645
A28: 2013-M02 | B28: 43.40625 | C28: 26 | D28: =C28^2 -> 676 | E28: =$Q$3*C28^2+$Q$5 -> 32.962027 | F28: =(B28-$Q$11)^2 -> 16.796443 | G28: =(E28-$Q$11)^2 -> 40.270152 | H28: =(B28-E28)^2 -> 109.0818
A29: 2013-M03 | B29: 42.28125 | C29: 27 | D29: =C29^2 -> 729 | E29: =$Q$3*C29^2+$Q$5 -> 32.995746 | F29: =(B29-$Q$11)^2 -> 8.8407884 | G29: =(E29-$Q$11)^2 -> 39.843334 | H29: =(B29-E29)^2 -> 86.220584
A30: 2013-M04 | B30: 41.4125 | C30: 28 | D30: =C30^2 -> 784 | E30: =$Q$3*C30^2+$Q$5 -> 33.030738 | F30: =(B30-$Q$11)^2 -> 4.4293257 | G30: =(E30-$Q$11)^2 -> 39.402814 | H30: =(B30-E30)^2 -> 70.253941
A31: 2013-M05 | B31: 40.605 | C31: 29 | D31: =C31^2 -> 841 | E31: =$Q$3*C31^2+$Q$5 -> 33.067002 | F31: =(B31-$Q$11)^2 -> 1.6824589 | G31: =(E31-$Q$11)^2 -> 38.948859 | H31: =(B31-E31)^2 -> 56.821421
... A180: 2025-M10 | B180: 63.958773 | C180: 178 | D180: =C180^2 -> 31684 | E180: =$Q$3*C180^2+$Q$5 -> 52.689627 | F180: =(B180-$Q$11)^2 -> 607.66538 | G180: =(E180-$Q$11)^2 -> 179.07052 | H180: =(B180-E180)^2 -> 126.99366
F182: ST = | G182: SM | H182: SR
F183: =SUM(F3:F180) -> 36060.832 | G183: =SUM(G3:G180) -> 6496.7314 | H183: =SUM(H3:H180) -> 29564.1
F184: R² | G184: =G183/F183 -> 0.18016033

Sheet Additf exponentiel
D1: Variable modifiée, Z | E1: Série ajustée par la tendance linéaire (z^) | F1: Série ajustée par la tendance exponentielle (y^) | G1: Contributions à SR (modèle exponentiel) | H1: Contributions à ST | I1: Contributions à SM
A2: TIME_PERIOD | B2: Yt | C2: t | D2: Zt =ln(Y) | E2: zt^=lnd+ct=0,0035*t+4 | F2: y^=54,7*exp(0,0035*t) | G2: et^2= (y-y^) au carré | H2: (z-zbar)^2 | I2: (z^-zbar)^2
A3: 2011-M01 | B3: 63.875 | C3: 1 | D3: =LN(B3) -> 4.156928 | E3: =SLOPE($D$3:$D$182,$C$3:$C$182)*$C3+INTERCEPT($D$3:$D$182,$C$3:$C$182) -> 3.5079421 | F3: =EXP(SLOPE($D$3:$D$182,$C$3:$C$182)*$C3)*EXP(INTERCEPT($D$3:$D$182,$C$3:$C$182)) -> 33.379504 | G3: =(F3-B3)^2 -> 929.97528 | H3: =(D3-AVERAGE($D$3:$D$182))^2 -> 0.30043637 | I3: =(E3-AVERAGE($D$3:$D$182))^2 -> 0.010173794 | O3: a (pente) | P3: =SLOPE(D3:D180,C3:C180) -> 0.0011397201 | R3: 2011 | S3: Janvier
A4: 2011-M02 | B4: 65 | C4: 2 | D4: =LN(B4) -> 4.1743873 | E4: =SLOPE($D$3:$D$182,$C$3:$C$182)*$C4+INTERCEPT($D$3:$D$182,$C$3:$C$182) -> 3.5090818 | F4: =EXP(SLOPE($D$3:$D$182,$C$3:$C$182)*$C4)*EXP(INTERCEPT($D$3:$D$182,$C$3:$C$182)) -> 33.417569 | G4: =(F4-B4)^2 -> 997.44995 | H4: =(D4-AVERAGE($D$3:$D$182))^2 -> 0.31988072 | I4: =(E4-AVERAGE($D$3:$D$182))^2 -> 0.0099451769 | S4: Février
A5: 2011-M03 | B5: 63.5 | C5: 3 | D5: =LN(B5) -> 4.1510399 | E5: =SLOPE($D$3:$D$182,$C$3:$C$182)*$C5+INTERCEPT($D$3:$D$182,$C$3:$C$182) -> 3.5102215 | F5: =EXP(SLOPE($D$3:$D$182,$C$3:$C$182)*$C5)*EXP(INTERCEPT($D$3:$D$182,$C$3:$C$182)) -> 33.455677 | G5: =(F5-B5)^2 -> 902.66132 | H5: =(D5-AVERAGE($D$3:$D$182))^2 -> 0.29401621 | I5: =(E5-AVERAGE($D$3:$D$182))^2 -> 0.0097191576 | O5: b (ordonnée à l'origine) | P5: =INTERCEPT(D3:D180,C3:C180) -> 3.5068023 | S5: Mars
A6: 2011-M04 | B6: 57.821429 | C6: 4 | D6: =LN(B6) -> 4.0573594 | E6: =SLOPE($D$3:$D$182,$C$3:$C$182)*$C6+INTERCEPT($D$3:$D$182,$C$3:$C$182) -> 3.5113612 | F6: =EXP(SLOPE($D$3:$D$182,$C$3:$C$182)*$C6)*EXP(INTERCEPT($D$3:$D$182,$C$3:$C$182)) -> 33.493829 | G6: =(F6-B6)^2 -> 591.83209 | H6: =(D6-AVERAGE($D$3:$D$182))^2 -> 0.20119904 | I6: =(E6-AVERAGE($D$3:$D$182))^2 -> 0.0094957361 | S6: Avril
A7: 2011-M05 | B7: 56.0625 | C7: 5 | D7: =LN(B7) -> 4.0264671 | E7: =SLOPE($D$3:$D$182,$C$3:$C$182)*$C7+INTERCEPT($D$3:$D$182,$C$3:$C$182) -> 3.5125009 | F7: =EXP(SLOPE($D$3:$D$182,$C$3:$C$182)*$C7)*EXP(INTERCEPT($D$3:$D$182,$C$3:$C$182)) -> 33.532025 | G7: =(F7-B7)^2 -> 507.62233 | H7: =(D7-AVERAGE($D$3:$D$182))^2 -> 0.17443975 | I7: =(E7-AVERAGE($D$3:$D$182))^2 -> 0.0092749126 | O7: COV(t²,Y) = | P7: =COVAR(D3:D180,C3:C180) -> 3.009146 | S7: Mai
A8: 2011-M06 | B8: 55.4 | C8: 6 | D8: =LN(B8) -> 4.0145796 | E8: =SLOPE($D$3:$D$182,$C$3:$C$182)*$C8+INTERCEPT($D$3:$D$182,$C$3:$C$182) -> 3.5136407 | F8: =EXP(SLOPE($D$3:$D$182,$C$3:$C$182)*$C8)*EXP(INTERCEPT($D$3:$D$182,$C$3:$C$182)) -> 33.570263 | G8: =(F8-B8)^2 -> 476.5374 | H8: =(D8-AVERAGE($D$3:$D$182))^2 -> 0.16465117 | I8: =(E8-AVERAGE($D$3:$D$182))^2 -> 0.009056687 | S8: Juin
A9: 2011-M07 | B9: 52.788889 | C9: 7 | D9: =LN(B9) -> 3.9663007 | E9: =SLOPE($D$3:$D$182,$C$3:$C$182)*$C9+INTERCEPT($D$3:$D$182,$C$3:$C$182) -> 3.5147804 | F9: =EXP(SLOPE($D$3:$D$182,$C$3:$C$182)*$C9)*EXP(INTERCEPT($D$3:$D$182,$C$3:$C$182)) -> 33.608546 | G9: =(F9-B9)^2 -> 367.88556 | H9: =(D9-AVERAGE($D$3:$D$182))^2 -> 0.12780156 | I9: =(E9-AVERAGE($D$3:$D$182))^2 -> 0.0088410593 | O9: tbar = moy t | P9: =AVERAGE(C3:C180) -> 89.5 | S9: Juillet
A10: 2011-M08 | B10: 50.683333 | C10: 8 | D10: =LN(B10) -> 3.9255971 | E10: =SLOPE($D$3:$D$182,$C$3:$C$182)*$C10+INTERCEPT($D$3:$D$182,$C$3:$C$182) -> 3.5159201 | F10: =EXP(SLOPE($D$3:$D$182,$C$3:$C$182)*$C10)*EXP(INTERCEPT($D$3:$D$182,$C$3:$C$182)) -> 33.646872 | G10: =(F10-B10)^2 -> 290.24101 | H10: =(D10-AVERAGE($D$3:$D$182))^2 -> 0.1003558 | I10: =(E10-AVERAGE($D$3:$D$182))^2 -> 0.0086280296 | S10: Aout
A11: 2011-M09 | B11: 51.983333 | C11: 9 | D11: =LN(B11) -> 3.9509232 | E11: =SLOPE($D$3:$D$182,$C$3:$C$182)*$C11+INTERCEPT($D$3:$D$182,$C$3:$C$182) -> 3.5170598 | F11: =EXP(SLOPE($D$3:$D$182,$C$3:$C$182)*$C11)*EXP(INTERCEPT($D$3:$D$182,$C$3:$C$182)) -> 33.685242 | G11: =(F11-B11)^2 -> 334.82015 | H11: =(D11-AVERAGE($D$3:$D$182))^2 -> 0.11704327 | I11: =(E11-AVERAGE($D$3:$D$182))^2 -> 0.0084175978 | O11: Zbar = moy Y | P11: =AVERAGE(D3:D180) -> 3.6088073 | S11: Septembre
A12: 2011-M10 | B12: 52.3375 | C12: 10 | D12: =LN(B12) -> 3.9577131 | E12: =SLOPE($D$3:$D$182,$C$3:$C$182)*$C12+INTERCEPT($D$3:$D$182,$C$3:$C$182) -> 3.5181995 | F12: =EXP(SLOPE($D$3:$D$182,$C$3:$C$182)*$C12)*EXP(INTERCEPT($D$3:$D$182,$C$3:$C$182)) -> 33.723656 | G12: =(F12-B12)^2 -> 346.4752 | H12: =(D12-AVERAGE($D$3:$D$182))^2 -> 0.12173529 | I12: =(E12-AVERAGE($D$3:$D$182))^2 -> 0.0082097639 | S12: Octobre
A13: 2011-M11 | B13: 53.194444 | C13: 11 | D13: =LN(B13) -> 3.973954 | E13: =SLOPE($D$3:$D$182,$C$3:$C$182)*$C13+INTERCEPT($D$3:$D$182,$C$3:$C$182) -> 3.5193393 | F13: =EXP(SLOPE($D$3:$D$182,$C$3:$C$182)*$C13)*EXP(INTERCEPT($D$3:$D$182,$C$3:$C$182)) -> 33.762113 | G13: =(F13-B13)^2 -> 377.6155 | H13: =(D13-AVERAGE($D$3:$D$182))^2 -> 0.1333321 | I13: =(E13-AVERAGE($D$3:$D$182))^2 -> 0.0080045279 | O13: Equation de la tendance sous ajustement linéaire : | P13: y=0,00064t + 32,532 | S13: Novembre
A14: 2011-M12 | B14: 52.178571 | C14: 12 | D14: =LN(B14) -> 3.9546719 | E14: =SLOPE($D$3:$D$182,$C$3:$C$182)*$C14+INTERCEPT($D$3:$D$182,$C$3:$C$182) -> 3.520479 | F14: =EXP(SLOPE($D$3:$D$182,$C$3:$C$182)*$C14)*EXP(INTERCEPT($D$3:$D$182,$C$3:$C$182)) -> 33.800614 | G14: =(F14-B14)^2 -> 337.74931 | H14: =(D14-AVERAGE($D$3:$D$182))^2 -> 0.11962233 | I14: =(E14-AVERAGE($D$3:$D$182))^2 -> 0.0078018898 | S14: Décembre
A15: 2012-M01 | B15: 52.3125 | C15: 13 | D15: =LN(B15) -> 3.9572353 | E15: =SLOPE($D$3:$D$182,$C$3:$C$182)*$C15+INTERCEPT($D$3:$D$182,$C$3:$C$182) -> 3.5216187 | F15: =EXP(SLOPE($D$3:$D$182,$C$3:$C$182)*$C15)*EXP(INTERCEPT($D$3:$D$182,$C$3:$C$182)) -> 33.83916 | G15: =(F15-B15)^2 -> 341.26431 | H15: =(D15-AVERAGE($D$3:$D$182))^2 -> 0.12140211 | I15: =(E15-AVERAGE($D$3:$D$182))^2 -> 0.0076018497 | O15: Var(Z) = | P15: =VARP(D3:D180) -> 0.12394034 | R15: 2012 | S15: Janvier
A16: 2012-M02 | B16: 52.055556 | C16: 14 | D16: =LN(B16) -> 3.9523115 | E16: =SLOPE($D$3:$D$182,$C$3:$C$182)*$C16+INTERCEPT($D$3:$D$182,$C$3:$C$182) -> 3.5227584 | F16: =EXP(SLOPE($D$3:$D$182,$C$3:$C$182)*$C16)*EXP(INTERCEPT($D$3:$D$182,$C$3:$C$182)) -> 33.877749 | G16: =(F16-B16)^2 -> 330.43266 | H16: =(D16-AVERAGE($D$3:$D$182))^2 -> 0.11799516 | I16: =(E16-AVERAGE($D$3:$D$182))^2 -> 0.0074044075 | S16: Février
A17: 2012-M03 | B17: 51.288889 | C17: 15 | D17: =LN(B17) -> 3.9374741 | E17: =SLOPE($D$3:$D$182,$C$3:$C$182)*$C17+INTERCEPT($D$3:$D$182,$C$3:$C$182) -> 3.5238981 | F17: =EXP(SLOPE($D$3:$D$182,$C$3:$C$182)*$C17)*EXP(INTERCEPT($D$3:$D$182,$C$3:$C$182)) -> 33.916382 | G17: =(F17-B17)^2 -> 301.804 | H17: =(D17-AVERAGE($D$3:$D$182))^2 -> 0.1080219 | I17: =(E17-AVERAGE($D$3:$D$182))^2 -> 0.0072095632 | O17: Var(t) = | P17: =VARP(C3:C180) -> 2640.25 | S17: Mars
A18: 2012-M04 | B18: 51.3 | C18: 16 | D18: =LN(B18) -> 3.9376908 | E18: =SLOPE($D$3:$D$182,$C$3:$C$182)*$C18+INTERCEPT($D$3:$D$182,$C$3:$C$182) -> 3.5250379 | F18: =EXP(SLOPE($D$3:$D$182,$C$3:$C$182)*$C18)*EXP(INTERCEPT($D$3:$D$182,$C$3:$C$182)) -> 33.955059 | G18: =(F18-B18)^2 -> 300.84697 | H18: =(D18-AVERAGE($D$3:$D$182))^2 -> 0.10816433 | I18: =(E18-AVERAGE($D$3:$D$182))^2 -> 0.0070173169 | S18: Avril
A19: 2012-M05 | B19: 51.888889 | C19: 17 | D19: =LN(B19) -> 3.9491047 | E19: =SLOPE($D$3:$D$182,$C$3:$C$182)*$C19+INTERCEPT($D$3:$D$182,$C$3:$C$182) -> 3.5261776 | F19: =EXP(SLOPE($D$3:$D$182,$C$3:$C$182)*$C19)*EXP(INTERCEPT($D$3:$D$182,$C$3:$C$182)) -> 33.99378 | G19: =(F19-B19)^2 -> 320.23491 | H19: =(D19-AVERAGE($D$3:$D$182))^2 -> 0.11580232 | I19: =(E19-AVERAGE($D$3:$D$182))^2 -> 0.0068276684 | O19: R² | P19: =CORREL(D3:D180,C3:C180) -> 0.16634678 | S19: Mai
A20: 2012-M06 | B20: 50.833333 | C20: 18 | D20: =LN(B20) -> 3.9285523 | E20: =SLOPE($D$3:$D$182,$C$3:$C$182)*$C20+INTERCEPT($D$3:$D$182,$C$3:$C$182) -> 3.5273173 | F20: =EXP(SLOPE($D$3:$D$182,$C$3:$C$182)*$C20)*EXP(INTERCEPT($D$3:$D$182,$C$3:$C$182)) -> 34.032546 | G20: =(F20-B20)^2 -> 282.26646 | H20: =(D20-AVERAGE($D$3:$D$182))^2 -> 0.10223688 | I20: =(E20-AVERAGE($D$3:$D$182))^2 -> 0.0066406179 | S20: Juin
A21: 2012-M07 | B21: 50.355556 | C21: 19 | D21: =LN(B21) -> 3.919109 | E21: =SLOPE($D$3:$D$182,$C$3:$C$182)*$C21+INTERCEPT($D$3:$D$182,$C$3:$C$182) -> 3.528457 | F21: =EXP(SLOPE($D$3:$D$182,$C$3:$C$182)*$C21)*EXP(INTERCEPT($D$3:$D$182,$C$3:$C$182)) -> 34.071356 | G21: =(F21-B21)^2 -> 265.17517 | H21: =(D21-AVERAGE($D$3:$D$182))^2 -> 0.096287124 | I21: =(E21-AVERAGE($D$3:$D$182))^2 -> 0.0064561653 | S21: Juillet
A22: 2012-M08 | B22: 49.25 | C22: 20 | D22: =LN(B22) -> 3.8969094 | E22: =SLOPE($D$3:$D$182,$C$3:$C$182)*$C22+INTERCEPT($D$3:$D$182,$C$3:$C$182) -> 3.5295967 | F22: =EXP(SLOPE($D$3:$D$182,$C$3:$C$182)*$C22)*EXP(INTERCEPT($D$3:$D$182,$C$3:$C$182)) -> 34.11021 | G22: =(F22-B22)^2 -> 229.21326 | H22: =(D22-AVERAGE($D$3:$D$182))^2 -> 0.08300281 | I22: =(E22-AVERAGE($D$3:$D$182))^2 -> 0.0062743107 | S22: Aout
A23: 2012-M09 | B23: 47.725 | C23: 21 | D23: =LN(B23) -> 3.8654554 | E23: =SLOPE($D$3:$D$182,$C$3:$C$182)*$C23+INTERCEPT($D$3:$D$182,$C$3:$C$182) -> 3.5307365 | F23: =EXP(SLOPE($D$3:$D$182,$C$3:$C$182)*$C23)*EXP(INTERCEPT($D$3:$D$182,$C$3:$C$182)) -> 34.149108 | G23: =(F23-B23)^2 -> 184.30485 | H23: =(D23-AVERAGE($D$3:$D$182))^2 -> 0.065868239 | I23: =(E23-AVERAGE($D$3:$D$182))^2 -> 0.0060950539 | S23: Septembre
A24: 2012-M10 | B24: 44.611111 | C24: 22 | D24: =LN(B24) -> 3.797983 | E24: =SLOPE($D$3:$D$182,$C$3:$C$182)*$C24+INTERCEPT($D$3:$D$182,$C$3:$C$182) -> 3.5318762 | F24: =EXP(SLOPE($D$3:$D$182,$C$3:$C$182)*$C24)*EXP(INTERCEPT($D$3:$D$182,$C$3:$C$182)) -> 34.18805 | G24: =(F24-B24)^2 -> 108.64019 | H24: =(D24-AVERAGE($D$3:$D$182))^2 -> 0.035787434 | I24: =(E24-AVERAGE($D$3:$D$182))^2 -> 0.0059183951 | S24: Octobre
A25: 2012-M11 | B25: 41.5 | C25: 23 | D25: =LN(B25) -> 3.7256934 | E25: =SLOPE($D$3:$D$182,$C$3:$C$182)*$C25+INTERCEPT($D$3:$D$182,$C$3:$C$182) -> 3.5330159 | F25: =EXP(SLOPE($D$3:$D$182,$C$3:$C$182)*$C25)*EXP(INTERCEPT($D$3:$D$182,$C$3:$C$182)) -> 34.227037 | G25: =(F25-B25)^2 -> 52.895985 | H25: =(D25-AVERAGE($D$3:$D$182))^2 -> 0.01366237 | I25: =(E25-AVERAGE($D$3:$D$182))^2 -> 0.0057443342 | S25: Novembre
A26: 2012-M12 | B26: 43.666667 | C26: 24 | D26: =LN(B26) -> 3.776585 | E26: =SLOPE($D$3:$D$182,$C$3:$C$182)*$C26+INTERCEPT($D$3:$D$182,$C$3:$C$182) -> 3.5341556 | F26: =EXP(SLOPE($D$3:$D$182,$C$3:$C$182)*$C26)*EXP(INTERCEPT($D$3:$D$182,$C$3:$C$182)) -> 34.266069 | G26: =(F26-B26)^2 -> 88.371238 | H26: =(D26-AVERAGE($D$3:$D$182))^2 -> 0.028149373 | I26: =(E26-AVERAGE($D$3:$D$182))^2 -> 0.0055728712 | S26: Décembre
A27: 2013-M01 | B27: 42.75 | C27: 25 | D27: =LN(B27) -> 3.7553692 | E27: =SLOPE($D$3:$D$182,$C$3:$C$182)*$C27+INTERCEPT($D$3:$D$182,$C$3:$C$182) -> 3.5352953 | F27: =EXP(SLOPE($D$3:$D$182,$C$3:$C$182)*$C27)*EXP(INTERCEPT($D$3:$D$182,$C$3:$C$182)) -> 34.305145 | G27: =(F27-B27)^2 -> 71.315578 | H27: =(D27-AVERAGE($D$3:$D$182))^2 -> 0.021480393 | I27: =(E27-AVERAGE($D$3:$D$182))^2 -> 0.0054040062 | R27: 2013 | S27: Janvier
A28: 2013-M02 | B28: 43.40625 | C28: 26 | D28: =LN(B28) -> 3.7706034 | E28: =SLOPE($D$3:$D$182,$C$3:$C$182)*$C28+INTERCEPT($D$3:$D$182,$C$3:$C$182) -> 3.5364351 | F28: =EXP(SLOPE($D$3:$D$182,$C$3:$C$182)*$C28)*EXP(INTERCEPT($D$3:$D$182,$C$3:$C$182)) -> 34.344265 | G28: =(F28-B28)^2 -> 82.119564 | H28: =(D28-AVERAGE($D$3:$D$182))^2 -> 0.026177995 | I28: =(E28-AVERAGE($D$3:$D$182))^2 -> 0.0052377391 | S28: Février
A29: 2013-M03 | B29: 42.28125 | C29: 27 | D29: =LN(B29) -> 3.7443437 | E29: =SLOPE($D$3:$D$182,$C$3:$C$182)*$C29+INTERCEPT($D$3:$D$182,$C$3:$C$182) -> 3.5375748 | F29: =EXP(SLOPE($D$3:$D$182,$C$3:$C$182)*$C29)*EXP(INTERCEPT($D$3:$D$182,$C$3:$C$182)) -> 34.383431 | G29: =(F29-B29)^2 -> 62.375551 | H29: =(D29-AVERAGE($D$3:$D$182))^2 -> 0.018370126 | I29: =(E29-AVERAGE($D$3:$D$182))^2 -> 0.0050740699 | S29: Mars
A30: 2013-M04 | B30: 41.4125 | C30: 28 | D30: =LN(B30) -> 3.7235828 | E30: =SLOPE($D$3:$D$182,$C$3:$C$182)*$C30+INTERCEPT($D$3:$D$182,$C$3:$C$182) -> 3.5387145 | F30: =EXP(SLOPE($D$3:$D$182,$C$3:$C$182)*$C30)*EXP(INTERCEPT($D$3:$D$182,$C$3:$C$182)) -> 34.42264 | G30: =(F30-B30)^2 -> 48.858137 | H30: =(D30-AVERAGE($D$3:$D$182))^2 -> 0.013173411 | I30: =(E30-AVERAGE($D$3:$D$182))^2 -> 0.0049129986 | S30: Avril
A31: 2013-M05 | B31: 40.605 | C31: 29 | D31: =LN(B31) -> 3.7038912 | E31: =SLOPE($D$3:$D$182,$C$3:$C$182)*$C31+INTERCEPT($D$3:$D$182,$C$3:$C$182) -> 3.5398542 | F31: =EXP(SLOPE($D$3:$D$182,$C$3:$C$182)*$C31)*EXP(INTERCEPT($D$3:$D$182,$C$3:$C$182)) -> 34.461895 | G31: =(F31-B31)^2 -> 37.737739 | H31: =(D31-AVERAGE($D$3:$D$182))^2 -> 0.009040953 | I31: =(E31-AVERAGE($D$3:$D$182))^2 -> 0.0047545252 | S31: Mai
A32: 2013-M06 | B32: 39.9375 | C32: 30 | D32: =LN(B32) -> 3.6873157 | E32: =SLOPE($D$3:$D$182,$C$3:$C$182)*$C32+INTERCEPT($D$3:$D$182,$C$3:$C$182) -> 3.5409939 | F32: =EXP(SLOPE($D$3:$D$182,$C$3:$C$182)*$C32)*EXP(INTERCEPT($D$3:$D$182,$C$3:$C$182)) -> 34.501194 | G32: =(F32-B32)^2 -> 29.55342 | H32: =(D32-AVERAGE($D$3:$D$182))^2 -> 0.0061635761 | I32: =(E32-AVERAGE($D$3:$D$182))^2 -> 0.0045986498 | S32: Juin
A33: 2013-M07 | B33: 38.022222 | C33: 31 | D33: =LN(B33) -> 3.6381708 | E33: =SLOPE($D$3:$D$182,$C$3:$C$182)*$C33+INTERCEPT($D$3:$D$182,$C$3:$C$182) -> 3.5421337 | F33: =EXP(SLOPE($D$3:$D$182,$C$3:$C$182)*$C33)*EXP(INTERCEPT($D$3:$D$182,$C$3:$C$182)) -> 34.540538 | G33: =(F33-B33)^2 -> 12.122122 | H33: =(D33-AVERAGE($D$3:$D$182))^2 -> 0.00086221503 | I33: =(E33-AVERAGE($D$3:$D$182))^2 -> 0.0044453723 | S33: Juillet
A34: 2013-M08 | B34: 34.994163 | C34: 32 | D34: =LN(B34) -> 3.5551813 | E34: =SLOPE($D$3:$D$182,$C$3:$C$182)*$C34+INTERCEPT($D$3:$D$182,$C$3:$C$182) -> 3.5432734 | F34: =EXP(SLOPE($D$3:$D$182,$C$3:$C$182)*$C34)*EXP(INTERCEPT($D$3:$D$182,$C$3:$C$182)) -> 34.579927 | G34: =(F34-B34)^2 -> 0.17159084 | H34: =(D34-AVERAGE($D$3:$D$182))^2 -> 0.00287575 | I34: =(E34-AVERAGE($D$3:$D$182))^2 -> 0.0042946927 | S34: Aout
A35: 2013-M09 | B35: 34.453287 | C35: 33 | D35: =LN(B35) -> 3.5396044 | E35: =SLOPE($D$3:$D$182,$C$3:$C$182)*$C35+INTERCEPT($D$3:$D$182,$C$3:$C$182) -> 3.5444131 | F35: =EXP(SLOPE($D$3:$D$182,$C$3:$C$182)*$C35)*EXP(INTERCEPT($D$3:$D$182,$C$3:$C$182)) -> 34.619361 | G35: =(F35-B35)^2 -> 0.027580756 | H35: =(D35-AVERAGE($D$3:$D$182))^2 -> 0.0047890395 | I35: =(E35-AVERAGE($D$3:$D$182))^2 -> 0.0041466111 | S35: Septembre
A36: 2013-M10 | B36: 34.848496 | C36: 34 | D36: =LN(B36) -> 3.55101 | E36: =SLOPE($D$3:$D$182,$C$3:$C$182)*$C36+INTERCEPT($D$3:$D$182,$C$3:$C$182) -> 3.5455528 | F36: =EXP(SLOPE($D$3:$D$182,$C$3:$C$182)*$C36)*EXP(INTERCEPT($D$3:$D$182,$C$3:$C$182)) -> 34.65884 | G36: =(F36-B36)^2 -> 0.035969176 | H36: =(D36-AVERAGE($D$3:$D$182))^2 -> 0.0033405299 | I36: =(E36-AVERAGE($D$3:$D$182))^2 -> 0.0040011274 | S36: Octobre
A37: 2013-M11 | B37: 35.592003 | C37: 35 | D37: =LN(B37) -> 3.572121 | E37: =SLOPE($D$3:$D$182,$C$3:$C$182)*$C37+INTERCEPT($D$3:$D$182,$C$3:$C$182) -> 3.5466925 | F37: =EXP(SLOPE($D$3:$D$182,$C$3:$C$182)*$C37)*EXP(INTERCEPT($D$3:$D$182,$C$3:$C$182)) -> 34.698364 | G37: =(F37-B37)^2 -> 0.79859073 | H37: =(D37-AVERAGE($D$3:$D$182))^2 -> 0.001345885 | I37: =(E37-AVERAGE($D$3:$D$182))^2 -> 0.0038582415 | S37: Novembre
A38: 2013-M12 | B38: 34.593297 | C38: 36 | D38: =LN(B38) -> 3.5436599 | E38: =SLOPE($D$3:$D$182,$C$3:$C$182)*$C38+INTERCEPT($D$3:$D$182,$C$3:$C$182) -> 3.5478323 | F38: =EXP(SLOPE($D$3:$D$182,$C$3:$C$182)*$C38)*EXP(INTERCEPT($D$3:$D$182,$C$3:$C$182)) -> 34.737933 | G38: =(F38-B38)^2 -> 0.020919554 | H38: =(D38-AVERAGE($D$3:$D$182))^2 -> 0.0042441769 | I38: =(E38-AVERAGE($D$3:$D$182))^2 -> 0.0037179537 | S38: Décembre
A39: 2014-M01 | B39: 35.214989 | C39: 37 | D39: =LN(B39) -> 3.5614718 | E39: =SLOPE($D$3:$D$182,$C$3:$C$182)*$C39+INTERCEPT($D$3:$D$182,$C$3:$C$182) -> 3.548972 | F39: =EXP(SLOPE($D$3:$D$182,$C$3:$C$182)*$C39)*EXP(INTERCEPT($D$3:$D$182,$C$3:$C$182)) -> 34.777547 | G39: =(F39-B39)^2 -> 0.19135537 | H39: =(D39-AVERAGE($D$3:$D$182))^2 -> 0.0022406468 | I39: =(E39-AVERAGE($D$3:$D$182))^2 -> 0.0035802637 | R39: 2014 | S39: Janvier
A40: 2014-M02 | B40: 35.546739 | C40: 38 | D40: =LN(B40) -> 3.5708484 | E40: =SLOPE($D$3:$D$182,$C$3:$C$182)*$C40+INTERCEPT($D$3:$D$182,$C$3:$C$182) -> 3.5501117 | F40: =EXP(SLOPE($D$3:$D$182,$C$3:$C$182)*$C40)*EXP(INTERCEPT($D$3:$D$182,$C$3:$C$182)) -> 34.817206 | G40: =(F40-B40)^2 -> 0.53221802 | H40: =(D40-AVERAGE($D$3:$D$182))^2 -> 0.0014408751 | I40: =(E40-AVERAGE($D$3:$D$182))^2 -> 0.0034451717 | S40: Février
...

Sheet LES quadratique
B1: LES Lissage | G1: Simulation de yt selon le poids du passé (constante de lissage) | P1: Formule de mise à jour avec initialisation : y^n(1) ou y^(n+1)
G2: Poids Faible | H2: Poids Moyen | I2: Poids Fort | K2: Contributions à la somme des carrés des erreurs de prévisions | P2: a *y^n-1 (1)+(1-a)*yn
G3: Alpha = 0,2 | H3: Alpha = 0,5 | I3: Alpha = 0,8 | L3: Alpha = 0,2 | M3: Alpha = 0,5 | N3: Alpha = 0,8
A4: TIME_PERIOD | B4: Années | C4: Mois | D4: Volume Yt | E4: Temps | G4: 0.2 | H4: 0.5 | I4: 0.8
A5: 2011-M01 | B5: =LEFT(TRIM(dataset_2025_11_17T13_30_33_170025752Z_DEFAULT_INTEGRATION_IMF_RES_PCPS_9_0_0[[#This Row],[TIME_PERIOD]]),4) -> 2011 | C5: Janvier | D5: 63.875 | E5: 1
A6: 2011-M02 | B6: =LEFT(TRIM(dataset_2025_11_17T13_30_33_170025752Z_DEFAULT_INTEGRATION_IMF_RES_PCPS_9_0_0[[#This Row],[TIME_PERIOD]]),4) -> 2011 | C6: Février | D6: 65 | E6: 2 | G6: =D5 -> 63.875 | H6: =D5 -> 63.875 | I6: =D5 -> 63.875 | L6: =(G6-$D6)^2 -> 1.265625 | M6: =(H6-$D6)^2 -> 1.265625 | N6: =(I6-$D6)^2 -> 1.265625
A7: 2011-M03 | B7: =LEFT(TRIM(dataset_2025_11_17T13_30_33_170025752Z_DEFAULT_INTEGRATION_IMF_RES_PCPS_9_0_0[[#This Row],[TIME_PERIOD]]),4) -> 2011 | C7: Mars | D7: 63.5 | E7: 3 | G7: =$G$4*G6+(1-$G$4)*D6 -> 64.775 | H7: =$H$4*G6+(1-$H$4)*D6 -> 64.4375 | I7: =$I$4*G6+(1-$I$4)*D6 -> 64.1 | L7: =(G7-$D7)^2 -> 1.625625 | M7: =(H7-$D7)^2 -> 0.87890625 | N7: =(I7-$D7)^2 -> 0.36
A8: 2011-M04 | B8: =LEFT(TRIM(dataset_2025_11_17T13_30_33_170025752Z_DEFAULT_INTEGRATION_IMF_RES_PCPS_9_0_0[[#This Row],[TIME_PERIOD]]),4) -> 2011 | C8: Avril | D8: 57.821429 | E8: 4 | G8: =$G$4*G7+(1-$G$4)*D7 -> 63.755 | H8: =$H$4*G7+(1-$H$4)*D7 -> 64.1375 | I8: =$I$4*G7+(1-$I$4)*D7 -> 64.52 | L8: =(G8-$D8)^2 -> 35.20727 | M8: =(H8-$D8)^2 -> 39.892758 | N8: =(I8-$D8)^2 -> 44.870859
A9: 2011-M05 | B9: =LEFT(TRIM(dataset_2025_11_17T13_30_33_170025752Z_DEFAULT_INTEGRATION_IMF_RES_PCPS_9_0_0[[#This Row],[TIME_PERIOD]]),4) -> 2011 | C9: Mai | D9: 56.0625 | E9: 5 | G9: =$G$4*G8+(1-$G$4)*D8 -> 59.008143 | H9: =$H$4*G8+(1-$H$4)*D8 -> 60.788214 | I9: =$I$4*G8+(1-$I$4)*D8 -> 62.568286 | L9: =(G9-$D9)^2 -> 8.6768118 | M9: =(H9-$D9)^2 -> 22.332376 | N9: =(I9-$D9)^2 -> 42.325248
A10: 2011-M06 | B10: =LEFT(TRIM(dataset_2025_11_17T13_30_33_170025752Z_DEFAULT_INTEGRATION_IMF_RES_PCPS_9_0_0[[#This Row],[TIME_PERIOD]]),4) -> 2011 | C10: Juin | D10: 55.4 | E10: 6 | G10: =$G$4*G9+(1-$G$4)*D9 -> 56.651629 | H10: =$H$4*G9+(1-$H$4)*D9 -> 57.535321 | I10: =$I$4*G9+(1-$I$4)*D9 -> 58.419014 | L10: =(G10-$D10)^2 -> 1.5665741 | M10: =(H10-$D10)^2 -> 4.5595976 | N10: =(I10-$D10)^2 -> 9.1144473
A11: 2011-M07 | B11: =LEFT(TRIM(dataset_2025_11_17T13_30_33_170025752Z_DEFAULT_INTEGRATION_IMF_RES_PCPS_9_0_0[[#This Row],[TIME_PERIOD]]),4) -> 2011 | C11: Juillet | D11: 52.788889 | E11: 7 | G11: =$G$4*G10+(1-$G$4)*D10 -> 55.650326 | H11: =$H$4*G10+(1-$H$4)*D10 -> 56.025814 | I11: =$I$4*G10+(1-$I$4)*D10 -> 56.401303 | L11: =(G11-$D11)^2 -> 8.1878207 | M11: =(H11-$D11)^2 -> 10.477686 | N11: =(I11-$D11)^2 -> 13.049535
A12: 2011-M08 | B12: =LEFT(TRIM(dataset_2025_11_17T13_30_33_170025752Z_DEFAULT_INTEGRATION_IMF_RES_PCPS_9_0_0[[#This Row],[TIME_PERIOD]]),4) -> 2011 | C12: Août | D12: 50.683333 | E12: 8 | G12: =$G$4*G11+(1-$G$4)*D11 -> 53.361176 | H12: =$H$4*G11+(1-$H$4)*D11 -> 54.219607 | I12: =$I$4*G11+(1-$I$4)*D11 -> 55.078038 | L12: =(G12-$D12)^2 -> 7.1708427 | M12: =(H12-$D12)^2 -> 12.505234 | N12: =(I12-$D12)^2 -> 19.313432
A13: 2011-M09 | B13: =LEFT(TRIM(dataset_2025_11_17T13_30_33_170025752Z_DEFAULT_INTEGRATION_IMF_RES_PCPS_9_0_0[[#This Row],[TIME_PERIOD]]),4) -> 2011 | C13: Septembre | D13: 51.983333 | E13: 9 | G13: =$G$4*G12+(1-$G$4)*D12 -> 51.218902 | H13: =$H$4*G12+(1-$H$4)*D12 -> 52.022255 | I13: =$I$4*G12+(1-$I$4)*D12 -> 52.825608 | L13: =(G13-$D13)^2 -> 0.58435539 | M13: =(H13-$D13)^2 -> 0.0015148801 | N13: =(I13-$D13)^2 -> 0.70942606
A14: 2011-M10 | B14: =LEFT(TRIM(dataset_2025_11_17T13_30_33_170025752Z_DEFAULT_INTEGRATION_IMF_RES_PCPS_9_0_0[[#This Row],[TIME_PERIOD]]),4) -> 2012 | C14: Octobre | D14: 52.3375 | E14: 10 | G14: =$G$4*G13+(1-$G$4)*D13 -> 51.830447 | H14: =$H$4*G13+(1-$H$4)*D13 -> 51.601118 | I14: =$I$4*G13+(1-$I$4)*D13 -> 51.371788 | L14: =(G14-$D14)^2 -> 0.25710269 | M14: =(H14-$D14)^2 -> 0.542259 | N14: =(I14-$D14)^2 -> 0.93259928
A15: 2011-M11 | B15: =LEFT(TRIM(dataset_2025_11_17T13_30_33_170025752Z_DEFAULT_INTEGRATION_IMF_RES_PCPS_9_0_0[[#This Row],[TIME_PERIOD]]),4) -> 2012 | C15: Novembre | D15: 53.194444 | E15: 11 | G15: =$G$4*G14+(1-$G$4)*D14 -> 52.236089 | H15: =$H$4*G14+(1-$H$4)*D14 -> 52.083974 | I15: =$I$4*G14+(1-$I$4)*D14 -> 51.931858 | L15: =(G15-$D15)^2 -> 0.91844437 | M15: =(H15-$D15)^2 -> 1.2331457 | N15: =(I15-$D15)^2 -> 1.5941254
A16: 2011-M12 | B16: =LEFT(TRIM(dataset_2025_11_17T13_30_33_170025752Z_DEFAULT_INTEGRATION_IMF_RES_PCPS_9_0_0[[#This Row],[TIME_PERIOD]]),4) -> 2012 | C16: Décembre | D16: 52.178571 | E16: 12 | G16: =$G$4*G15+(1-$G$4)*D15 -> 53.002773 | H16: =$H$4*G15+(1-$H$4)*D15 -> 52.715267 | I16: =$I$4*G15+(1-$I$4)*D15 -> 52.42776 | L16: =(G16-$D16)^2 -> 0.67930895 | M16: =(H16-$D16)^2 -> 0.28804206 | N16: =(I16-$D16)^2 -> 0.062095152
A17: 2012-M01 | B17: =LEFT(TRIM(dataset_2025_11_17T13_30_33_170025752Z_DEFAULT_INTEGRATION_IMF_RES_PCPS_9_0_0[[#This Row],[TIME_PERIOD]]),4) -> 2012 | C17: Janvier | D17: 52.3125 | E17: 13 | G17: =$G$4*G16+(1-$G$4)*D16 -> 52.343412 | H17: =$H$4*G16+(1-$H$4)*D16 -> 52.590672 | I17: =$I$4*G16+(1-$I$4)*D16 -> 52.837933 | L17: =(G17-$D17)^2 -> 0.00095554126 | M17: =(H17-$D17)^2 -> 0.077379903 | N17: =(I17-$D17)^2 -> 0.27607988
A18: 2012-M02 | B18: =LEFT(TRIM(dataset_2025_11_17T13_30_33_170025752Z_DEFAULT_INTEGRATION_IMF_RES_PCPS_9_0_0[[#This Row],[TIME_PERIOD]]),4) -> 2012 | C18: Février | D18: 52.055556 | E18: 14 | G18: =$G$4*G17+(1-$G$4)*D17 -> 52.318682 | H18: =$H$4*G17+(1-$H$4)*D17 -> 52.327956 | I18: =$I$4*G17+(1-$I$4)*D17 -> 52.337229 | L18: =(G18-$D18)^2 -> 0.069235718 | M18: =(H18-$D18)^2 -> 0.074201956 | N18: =(I18-$D18)^2 -> 0.079340191
... A179: 2025-M07 | B179: =LEFT(TRIM(dataset_2025_11_17T13_30_33_170025752Z_DEFAULT_INTEGRATION_IMF_RES_PCPS_9_0_0[[#This Row],[TIME_PERIOD]]),4) -> 2025 | C179: Juillet | D179: 58.947255 | E179: 175 | G179: =$G$4*G178+(1-$G$4)*D178 -> 58.936299 | H179: =$H$4*G178+(1-$H$4)*D178 -> 57.975955 | I179: =$I$4*G178+(1-$I$4)*D178 -> 57.01561 | L179: =(G179-$D179)^2 -> 0.00012004166 | M179: =(H179-$D179)^2 -> 0.94342523 | N179: =(I179-$D179)^2 -> 3.7312533
A180: 2025-M08 | B180: 2025 | C180: Août | D180: 58.966662 | E180: 176 | G180: =$G$4*G179+(1-$G$4)*D179 -> 58.945064 | H180: =$H$4*G179+(1-$H$4)*D179 -> 58.941777 | I180: =$I$4*G179+(1-$I$4)*D179 -> 58.93849 | L180: =(G180-$D180)^2 -> 0.00046644245 | M180: =(H180-$D180)^2 -> 0.00061922264 | N180: =(I180-$D180)^2 -> 0.00079361032
A181: 2025-M09 | B181: 2025 | C181: Septembre | D181: 62.875444 | E181: 177 | G181: =$G$4*G180+(1-$G$4)*D180 -> 58.962342 | H181: =$H$4*G180+(1-$H$4)*D180 -> 58.955863 | I181: =$I$4*G180+(1-$I$4)*D180 -> 58.949384 | L181: =(G181-$D181)^2 -> 15.312365 | M181: =(H181-$D181)^2 -> 15.363114 | N181: =(I181-$D181)^2 -> 15.413947
A182: 2025-M10 | B182: 2025 | C182: Octobre | D182: 63.958773 | E182: 178 | G182: =$G$4*G181+(1-$G$4)*D181 -> 62.092823 | H182: =$H$4*G181+(1-$H$4)*D181 -> 60.918893 | I182: =$I$4*G181+(1-$I$4)*D181 -> 59.744962 | L182: =(G182-$D182)^2 -> 3.4817697 | M182: =(H182-$D182)^2 -> 9.240874 | N182: =(I182-$D182)^2 -> 17.756204
K184: Erreurs de prévisions | L184: =SUM(L6:L182) -> 1479.463 | M184: =SUM(M6:M182) -> 1936.5692 | N184: =SUM(N6:N182) -> 2659.3519

